Workbook

Sheet INICIO
C1: CONTROL DE PROYECTO | F1: Hoja de inicio: diligencie las celdas amarillas. Todo lo demás se calcula solo.
B2: ● INICIO | C2: TABLERO | D2: CRONOGRAMA | E2: PRESUPUESTO | F2: CORTES CLIENTE | H2: MANO DE OBRA | I2: GASTOS | K2: MATERIALES | M2: GUÍA
B4: DATOS DEL PROYECTO | G4: VALOR DEL CONTRATO (calculado)
B5: Nombre del proyecto | G5: Costo directo (valor de venta de ítems) | H5: =PRESUPUESTO!G5 -> 0
B6: Cliente | G6: Administración | H6: =v_CD*p_Admin -> 0
B7: Ciudad | G7: Imprevistos | H7: =v_CD*p_Imprev -> 0
B8: N° cotización / referencia | G8: Utilidad | H8: =v_CD*p_Util -> 0
B9: Fecha de cotización | G9: IVA sobre utilidad | H9: =v_CD*p_Util*p_IVA -> 0
B10: Fecha de inicio de obra | G10: TOTAL CONTRATO | H10: =SUM(H5:H9) -> 0
B11: Fecha fin contractual | G11: Ingreso del proyecto sin IVA (CD + A + I + U) | H11: =SUM(H5:H8) -> 0
B12: Director de proyecto | G12: Valor del anticipo | H12: =v_Total*p_Anticipo -> 0
B13: Comercial responsable
B14: Contratista de mano de obra | G14: TARIFAS TÉCNICOS PROPIOS
B15: Estado del proyecto | G15: Cargo | H15: Valor hora | I15: Horas / día | J15: Valor día
G16: Técnico electricista | H16: 12000 | I16: 8 | J16: =IF(G16="","",H16*I16) -> 96000
B17: PARÁMETROS FINANCIEROS | G17: Técnico de redes / CCTV | H17: 12000 | I17: 8 | J17: =IF(G17="","",H17*I17) -> 96000
B18: Administración (A) | C18: 0.08 | D18: Sobre costo directo de venta | G18: Auxiliar técnico | H18: 8500 | I18: 8 | J18: =IF(G18="","",H18*I18) -> 68000
B19: Imprevistos (I) | C19: 0.03 | G19: Supervisor / Ingeniero residente | H19: 25000 | I19: 8 | J19: =IF(G19="","",H19*I19) -> 200000
B20: Utilidad (U) | C20: 0.05 | J20: =IF(G20="","",H20*I20)
B21: IVA | C21: 0.19 | D21: Se cobra sobre la utilidad (esquema AIU) | J21: =IF(G21="","",H21*I21)
B22: ¿Sumar IVA al costo de materiales? | C22: Sí | D22: En AIU el IVA de compras es costo | J22: =IF(G22="","",H22*I22)
B23: Anticipo pactado | C23: 0.3 | D23: Se amortiza en cada acta | J23: =IF(G23="","",H23*I23)
B24: Impuestos (% sobre costo directo) | C24: 0.051 | D24: Tomado del cotizador | G24: Valores de EJEMPLO: reemplace por las tarifas reales de la empresa.
B25: Pólizas (% sobre total contrato) | C25: 0.015 | D25: Tomado del cotizador
B26: Gastos legales (% sobre costo directo) | C26: 0.001 | D26: Tomado del cotizador (abogado) | G26: CÓMO SE USA (código de colores)
B27: Recargo hora extra técnicos | C27: 0.25 | D27: Supuesto — confirmar | G27: Celda amarilla, letra azul | H27: Dato que USTED digita
B28: Anticipo recibido ($) | D28: Digite el valor cuando entre | G28: Celda blanca, letra negra | H28: Fórmula: no se toca
G29: Fila azul claro | H29: Capítulo / agrupador
B30: ÍNDICE DEL LIBRO | G30: Rojo / ámbar / verde | H30: Semáforo de alertas
B31: TABLERO | C31: Tablero: margen, avance, facturación y alertas
B32: CRONOGRAMA | C32: Hitos y frentes con fechas, Gantt y alertas de atraso | G32: • Para un proyecto nuevo: guarde una copia de la PLANTILLA, llene INICIO y pegue los ítems de la cotización en PRESUPUESTO.
B33: PRESUPUESTO | C33: Ítems de la cotización con costos (base de todo)
B34: CORTES CLIENTE | C34: Avance de obra, actas y facturación al cliente | G34: • Agregue ítems en las filas vacías al final del PRESUPUESTO; no inserte filas en medio (las demás hojas se alinean por fila).
B35: MANO DE OBRA | C35: Contratista (contrato y cortes) + horas de técnicos propios
B36: GASTOS | C36: ÚNICA hoja de registro: compras, suministros, alquileres, transporte y pagos | G36: • Todo gasto (compras, alquileres, transporte, pagos al contratista) se escribe UNA sola vez en GASTOS: una fila por ítem comprado o por pago.
B37: CONTROL DE MATERIALES | C37: Por ítem: comprado, faltante, precio promedio y alertas (solo lectura)
B38: GUÍA APP | C38: Cómo pasar este modelo al desarrollo web

Sheet TABLERO
D1: TABLERO DEL PROYECTO | H1: Se actualiza solo con lo que se digita en las demás hojas.
B2: INICIO | C2: ● TABLERO | D2: CRONOGRAMA | E2: PRESUPUESTO | F2: CORTES CLIENTE | G2: MANO DE OBRA | H2: GASTOS | I2: MATERIALES | J2: GUÍA
B3: =n_Proyecto&" · Cliente: "&n_Cliente&" · "&n_Cotizacion&" · Corte al "&TEXT(TODAY(),"dd/mm/yyyy") -> · Cliente: · · Corte al 17/10/2026
B5: VALOR DEL CONTRATO | E5: AVANCE FÍSICO | H5: FACTURADO (neto) | K5: COSTO REAL A LA FECHA | N5: MARGEN BRUTO PROYECTADO
B6: =v_Total -> 0 | E6: ='CORTES CLIENTE'!$N$18 | H6: =(SUMIF('CORTES CLIENTE'!$F$16:$K$16,"Facturado",'CORTES CLIENTE'!$F$13:$K$13)+SUMIF('CORTES CLIENTE'!$F$16:$K$16,"Pagado",'CORTES CLIENTE'!$F$13:$K$13))+N(p_AntRecibido) -> 0 | K6: =E16 -> 0 | N6: =F24
B7: ="Ingreso sin IVA: "&TEXT(v_Ingreso,"$#,##0") -> Ingreso sin IVA: $0 | E7: ="Ejecutado: "&TEXT('CORTES CLIENTE'!$O$18,"$#,##0") -> Ejecutado: $0 | H7: ="Incluye anticipo recibido · "&TEXT(IF(v_Total=0,0,((SUMIF('CORTES CLIENTE'!$F$16:$K$16,"Facturado",'CORTES CLIENTE'!$F$13:$K$13)+SUMIF('CORTES CLIENTE'!$F$16:$K$16,"Pagado",'CORTES CLIENTE'!$F$13:$K$13))+N(p_AntRecibido))/v_Total),"0%")&" del contrato" -> Incluye anticipo recibido · 0% del contrato | K7: ="Consumido: "&TEXT(IF(D16=0,0,E16/D16),"0.0%")&" del presupuesto" -> Consumido: 0.0% del presupuesto | N7: ="Al cierre: "&TEXT(E24,"$#,##0") -> Al cierre: $0
B9: CONTROL DE COSTOS POR CATEGORÍA
B10: Categoría | D10: Presupuesto | E10: Real a la fecha | F10: % consumido | G10: Saldo disponible | H10: Proyección al cierre | I10: Desviación | J10: Estado | K10: Regla de proyección
B11: Materiales y equipos | D11: =PRESUPUESTO!O5 -> 0 | E11: =SUMIFS(GASTOS!$J$7:$J$5000,GASTOS!$L$7:$L$5000,"Materiales y equipos") -> 0 | F11: =IF(D11=0,"",E11/D11) | G11: =D11-E11 -> 0 | H11: =E11+v_FaltMat -> 0 | I11: =H11-D11 -> 0 | J11: =IF(H11>D11+1,"Sobrecosto",IF(IF(D11>0,E11/D11,0)>N('CORTES CLIENTE'!$N$18)+0.15,"Atención","En control")) -> En control | K11: Real + faltante valorizado (CONTROL DE MATERIALES)
B12: Mano de obra | D12: =PRESUPUESTO!P5 -> 0 | E12: =SUMIFS(GASTOS!$J$7:$J$5000,GASTOS!$L$7:$L$5000,"Mano de obra contratista")+v_MOPropia -> 0 | F12: =IF(D12=0,"",E12/D12) | G12: =D12-E12 -> 0 | H12: =MAX(E12,'MANO DE OBRA'!$H$11+v_MOPropia) -> 0 | I12: =H12-D12 -> 0 | J12: =IF(H12>D12+1,"Sobrecosto",IF(IF(D12>0,E12/D12,0)>N('CORTES CLIENTE'!$N$18)+0.15,"Atención","En control")) -> En control | K12: Contrato contratista + MO propia
B13: Transporte y otros | D13: =PRESUPUESTO!Q5 -> 0 | E13: =SUMIFS(GASTOS!$J$7:$J$5000,GASTOS!$L$7:$L$5000,"Transporte y otros") -> 0 | F13: =IF(D13=0,"",E13/D13) | G13: =D13-E13 -> 0 | H13: =MAX(D13,E13) -> 0 | I13: =H13-D13 -> 0 | J13: =IF(H13>D13+1,"Sobrecosto",IF(IF(D13>0,E13/D13,0)>N('CORTES CLIENTE'!$N$18)+0.15,"Atención","En control")) -> En control | K13: Mayor entre real y presupuesto
B14: Alquileres | D14: =PRESUPUESTO!R5 -> 0 | E14: =SUMIFS(GASTOS!$J$7:$J$5000,GASTOS!$L$7:$L$5000,"Alquileres") -> 0 | F14: =IF(D14=0,"",E14/D14) | G14: =D14-E14 -> 0 | H14: =MAX(D14,E14) -> 0 | I14: =H14-D14 -> 0 | J14: =IF(H14>D14+1,"Sobrecosto",IF(IF(D14>0,E14/D14,0)>N('CORTES CLIENTE'!$N$18)+0.15,"Atención","En control")) -> En control | K14: Mayor entre real y presupuesto
B15: Impuestos y pólizas | D15: =v_CD*(p_Impuestos+p_Legales)+v_Total*p_Polizas -> 0 | E15: =D15*N('CORTES CLIENTE'!$N$18) -> 0 | F15: =IF(D15=0,"",E15/D15) | G15: =D15-E15 -> 0 | H15: =D15 -> 0 | I15: =H15-D15 -> 0 | J15: En control | K15: Se causan según avance
B16: TOTAL | D16: =SUM(D11:D15) -> 0 | E16: =SUM(E11:E15) -> 0 | F16: =IF(D16=0,"",E16/D16) | G16: =SUM(G11:G15) -> 0 | H16: =SUM(H11:H15) -> 0 | I16: =SUM(I11:I15) -> 0 | J16: =IF(H16>D16+1,"Sobrecosto","En control") -> En control
B18: MARGEN BRUTO | H18: FACTURACIÓN Y CARTERA
B19: Concepto | E19: Valor | F19: % | H19: Concepto | K19: Valor
B20: Ingreso del contrato (sin IVA) | E20: =v_Ingreso -> 0 | H20: Valor total del contrato (con IVA) | K20: =v_Total -> 0
B21: Costo presupuestado total | E21: =D16 -> 0 | H21: Anticipo pactado | K21: =v_Anticipo -> 0
B22: MARGEN BRUTO PRESUPUESTADO | E22: =E20-E21 -> 0 | F22: =IF(E20=0,"",E22/E20) | H22: Anticipo recibido | K22: =N(p_AntRecibido) -> 0
B23: Costo proyectado al cierre | E23: =H16 -> 0 | H23: Total actas generadas | K23: ='CORTES CLIENTE'!L11 -> 0
B24: MARGEN BRUTO PROYECTADO | E24: =E20-E23 -> 0 | F24: =IF(E20=0,"",E24/E20) | H24: Facturado en actas (neto) | K24: =(SUMIF('CORTES CLIENTE'!$F$16:$K$16,"Facturado",'CORTES CLIENTE'!$F$13:$K$13)+SUMIF('CORTES CLIENTE'!$F$16:$K$16,"Pagado",'CORTES CLIENTE'!$F$13:$K$13)) -> 0
B25: Ingreso causado a la fecha (actas sin IVA) | E25: =SUM('CORTES CLIENTE'!L6:L9) -> 0 | H25: Recaudado (actas + anticipo) | K25: ='CORTES CLIENTE'!L17+N(p_AntRecibido) -> 0
B26: Costo real a la fecha | E26: =E16 -> 0 | H26: SALDO DEL CONTRATO POR EJECUTAR | K26: =v_Total-'CORTES CLIENTE'!L11 -> 0
B27: MARGEN REAL A LA FECHA | E27: =E25-E26 -> 0 | F27: =IF(E25=0,"",E27/E25) | H27: CARTERA POR COBRAR | K27: =K24-'CORTES CLIENTE'!L17 -> 0
B29: PRESUPUESTO vs REAL vs PROYECCIÓN | I29: GASTOS POR TIPO (desde GASTOS)
I30: Tipo | L30: Valor | M30: % del total | N30: N° registros
I31: Material | L31: =SUMIFS(GASTOS!$J$7:$J$5000,GASTOS!$C$7:$C$5000,I31) -> 0 | M31: =IF(L$37=0,"",L31/L$37) | N31: =COUNTIF(GASTOS!$C$7:$C$5000,I31) -> 0
I32: Equipo | L32: =SUMIFS(GASTOS!$J$7:$J$5000,GASTOS!$C$7:$C$5000,I32) -> 0 | M32: =IF(L$37=0,"",L32/L$37) | N32: =COUNTIF(GASTOS!$C$7:$C$5000,I32) -> 0
I33: Suministro | L33: =SUMIFS(GASTOS!$J$7:$J$5000,GASTOS!$C$7:$C$5000,I33) -> 0 | M33: =IF(L$37=0,"",L33/L$37) | N33: =COUNTIF(GASTOS!$C$7:$C$5000,I33) -> 0
I34: Alquiler | L34: =SUMIFS(GASTOS!$J$7:$J$5000,GASTOS!$C$7:$C$5000,I34) -> 0 | M34: =IF(L$37=0,"",L34/L$37) | N34: =COUNTIF(GASTOS!$C$7:$C$5000,I34) -> 0
I35: Transporte | L35: =SUMIFS(GASTOS!$J$7:$J$5000,GASTOS!$C$7:$C$5000,I35) -> 0 | M35: =IF(L$37=0,"",L35/L$37) | N35: =COUNTIF(GASTOS!$C$7:$C$5000,I35) -> 0
I36: Mano de obra contratista | L36: =SUMIFS(GASTOS!$J$7:$J$5000,GASTOS!$C$7:$C$5000,I36) -> 0 | M36: =IF(L$37=0,"",L36/L$37) | N36: =COUNTIF(GASTOS!$C$7:$C$5000,I36) -> 0
I37: TOTAL GASTADO | L37: =SUM(L31:L36) -> 0 | M37: =IF(L37=0,"",SUM(M31:M36)) | N37: =SUM(N31:N36) -> 0

Sheet CRONOGRAMA
D1: CRONOGRAMA DE OBRA | G1: Fases separadas por color. Digite duración y predecesora (o inicio fijo); al poner fechas REALES todo lo que depende se corre solo. Use los botones [-]/[+] de la izquierda para contraer o expandir cada fase.
B2: INICIO | D2: TABLERO | F2: ● CRONOGRAMA | G2: PRESUPUESTO | I2: CORTES CLIENTE | K2: MANO DE OBRA | M2: GASTOS | O2: MATERIALES | Q2: GUÍA
B3: INICIO | D3: FIN PROYECTADO | F3: FIN CONTRACTUAL | H3: HOLGURA (días) | J3: AVANCE FÍSICO | M3: HITOS CUMPLIDOS | O3: ATRASADAS
B4: =IF(COUNT($J$8:$J$36)=0,"",MIN($J$8:$J$36)) -> 46312 | D4: =IF(COUNT($K$8:$K$36)=0,"",MAX($K$8:$K$36)) -> 46348 | F4: =IF(n_FFin="","Sin definir",n_FFin) -> Sin definir | H4: =IF(OR(n_FFin="",COUNT($K$8:$K$36)=0),"",n_FFin-MAX($K$8:$K$36)) | J4: ='CORTES CLIENTE'!N18 | M4: =COUNTIFS($D$8:$D$36,"Hito",$P$8:$P$36,"Cumplido")&" / "&COUNTIF($D$8:$D$36,"Hito") -> 0 / 6 | O4: =COUNTIF($P$8:$P$36,"Atrasada")+COUNTIF($P$8:$P$36,"Vencido") -> 0
Y5: =TEXT(Y7,"yyyy") -> 2026 | Z5: =IF(1=0,TEXT(Z7,"yyyy"),IF(YEAR(Z7)<>YEAR(Y7),TEXT(Z7,"yyyy"),"")) | AA5: =IF(2=0,TEXT(AA7,"yyyy"),IF(YEAR(AA7)<>YEAR(Z7),TEXT(AA7,"yyyy"),"")) | AB5: =IF(3=0,TEXT(AB7,"yyyy"),IF(YEAR(AB7)<>YEAR(AA7),TEXT(AB7,"yyyy"),"")) | AC5: =IF(4=0,TEXT(AC7,"yyyy"),IF(YEAR(AC7)<>YEAR(AB7),TEXT(AC7,"yyyy"),"")) | AD5: =IF(5=0,TEXT(AD7,"yyyy"),IF(YEAR(AD7)<>YEAR(AC7),TEXT(AD7,"yyyy"),"")) | AE5: =IF(6=0,TEXT(AE7,"yyyy"),IF(YEAR(AE7)<>YEAR(AD7),TEXT(AE7,"yyyy"),"")) | AF5: =IF(7=0,TEXT(AF7,"yyyy"),IF(YEAR(AF7)<>YEAR(AE7),TEXT(AF7,"yyyy"),"")) | AG5: =IF(8=0,TEXT(AG7,"yyyy"),IF(YEAR(AG7)<>YEAR(AF7),TEXT(AG7,"yyyy"),"")) | AH5: =IF(9=0,TEXT(AH7,"yyyy"),IF(YEAR(AH7)<>YEAR(AG7),TEXT(AH7,"yyyy"),"")) | AI5: =IF(10=0,TEXT(AI7,"yyyy"),IF(YEAR(AI7)<>YEAR(AH7),TEXT(AI7,"yyyy"),"")) | AJ5: =IF(11=0,TEXT(AJ7,"yyyy"),IF(YEAR(AJ7)<>YEAR(AI7),TEXT(AJ7,"yyyy"),"")) | AK5: =IF(12=0,TEXT(AK7,"yyyy"),IF(YEAR(AK7)<>YEAR(AJ7),TEXT(AK7,"yyyy"),"")) -> 2027 | AL5: =IF(13=0,TEXT(AL7,"yyyy"),IF(YEAR(AL7)<>YEAR(AK7),TEXT(AL7,"yyyy"),"")) | AM5: =IF(14=0,TEXT(AM7,"yyyy"),IF(YEAR(AM7)<>YEAR(AL7),TEXT(AM7,"yyyy"),"")) | AN5: =IF(15=0,TEXT(AN7,"yyyy"),IF(YEAR(AN7)<>YEAR(AM7),TEXT(AN7,"yyyy"),"")) | AO5: =IF(16=0,TEXT(AO7,"yyyy"),IF(YEAR(AO7)<>YEAR(AN7),TEXT(AO7,"yyyy"),"")) | AP5: =IF(17=0,TEXT(AP7,"yyyy"),IF(YEAR(AP7)<>YEAR(AO7),TEXT(AP7,"yyyy"),"")) | AQ5: =IF(18=0,TEXT(AQ7,"yyyy"),IF(YEAR(AQ7)<>YEAR(AP7),TEXT(AQ7,"yyyy"),"")) | AR5: =IF(19=0,TEXT(AR7,"yyyy"),IF(YEAR(AR7)<>YEAR(AQ7),TEXT(AR7,"yyyy"),"")) | AS5: =IF(20=0,TEXT(AS7,"yyyy"),IF(YEAR(AS7)<>YEAR(AR7),TEXT(AS7,"yyyy"),"")) | AT5: =IF(21=0,TEXT(AT7,"yyyy"),IF(YEAR(AT7)<>YEAR(AS7),TEXT(AT7,"yyyy"),"")) | AU5: =IF(22=0,TEXT(AU7,"yyyy"),IF(YEAR(AU7)<>YEAR(AT7),TEXT(AU7,"yyyy"),"")) | AV5: =IF(23=0,TEXT(AV7,"yyyy"),IF(YEAR(AV7)<>YEAR(AU7),TEXT(AV7,"yyyy"),"")) | AW5: =IF(24=0,TEXT(AW7,"yyyy"),IF(YEAR(AW7)<>YEAR(AV7),TEXT(AW7,"yyyy"),"")) | AX5: =IF(25=0,TEXT(AX7,"yyyy"),IF(YEAR(AX7)<>YEAR(AW7),TEXT(AX7,"yyyy"),"")) | AY5: =IF(26=0,TEXT(AY7,"yyyy"),IF(YEAR(AY7)<>YEAR(AX7),TEXT(AY7,"yyyy"),"")) | AZ5: =IF(27=0,TEXT(AZ7,"yyyy"),IF(YEAR(AZ7)<>YEAR(AY7),TEXT(AZ7,"yyyy"),"")) | BA5: =IF(28=0,TEXT(BA7,"yyyy"),IF(YEAR(BA7)<>YEAR(AZ7),TEXT(BA7,"yyyy"),"")) | BB5: =IF(29=0,TEXT(BB7,"yyyy"),IF(YEAR(BB7)<>YEAR(BA7),TEXT(BB7,"yyyy"),"")) | BC5: =IF(30=0,TEXT(BC7,"yyyy"),IF(YEAR(BC7)<>YEAR(BB7),TEXT(BC7,"yyyy"),"")) | BD5: =IF(31=0,TEXT(BD7,"yyyy"),IF(YEAR(BD7)<>YEAR(BC7),TEXT(BD7,"yyyy"),"")) | BE5: =IF(32=0,TEXT(BE7,"yyyy"),IF(YEAR(BE7)<>YEAR(BD7),TEXT(BE7,"yyyy"),"")) | BF5: =IF(33=0,TEXT(BF7,"yyyy"),IF(YEAR(BF7)<>YEAR(BE7),TEXT(BF7,"yyyy"),"")) | BG5: =IF(34=0,TEXT(BG7,"yyyy"),IF(YEAR(BG7)<>YEAR(BF7),TEXT(BG7,"yyyy"),"")) | BH5: =IF(35=0,TEXT(BH7,"yyyy"),IF(YEAR(BH7)<>YEAR(BG7),TEXT(BH7,"yyyy"),"")) | BI5: =IF(36=0,TEXT(BI7,"yyyy"),IF(YEAR(BI7)<>YEAR(BH7),TEXT(BI7,"yyyy"),"")) | BJ5: =IF(37=0,TEXT(BJ7,"yyyy"),IF(YEAR(BJ7)<>YEAR(BI7),TEXT(BJ7,"yyyy"),"")) | BK5: =IF(38=0,TEXT(BK7,"yyyy"),IF(YEAR(BK7)<>YEAR(BJ7),TEXT(BK7,"yyyy"),"")) | BL5: =IF(39=0,TEXT(BL7,"yyyy"),IF(YEAR(BL7)<>YEAR(BK7),TEXT(BL7,"yyyy"),"")) | BM5: =IF(40=0,TEXT(BM7,"yyyy"),IF(YEAR(BM7)<>YEAR(BL7),TEXT(BM7,"yyyy"),"")) | BN5: =IF(41=0,TEXT(BN7,"yyyy"),IF(YEAR(BN7)<>YEAR(BM7),TEXT(BN7,"yyyy"),"")) | BO5: =IF(42=0,TEXT(BO7,"yyyy"),IF(YEAR(BO7)<>YEAR(BN7),TEXT(BO7,"yyyy"),"")) | BP5: =IF(43=0,TEXT(BP7,"yyyy"),IF(YEAR(BP7)<>YEAR(BO7),TEXT(BP7,"yyyy"),"")) | BQ5: =IF(44=0,TEXT(BQ7,"yyyy"),IF(YEAR(BQ7)<>YEAR(BP7),TEXT(BQ7,"yyyy"),"")) | BR5: =IF(45=0,TEXT(BR7,"yyyy"),IF(YEAR(BR7)<>YEAR(BQ7),TEXT(BR7,"yyyy"),"")) | BS5: =IF(46=0,TEXT(BS7,"yyyy"),IF(YEAR(BS7)<>YEAR(BR7),TEXT(BS7,"yyyy"),"")) | BT5: =IF(47=0,TEXT(BT7,"yyyy"),IF(YEAR(BT7)<>YEAR(BS7),TEXT(BT7,"yyyy"),"")) | BU5: =IF(48=0,TEXT(BU7,"yyyy"),IF(YEAR(BU7)<>YEAR(BT7),TEXT(BU7,"yyyy"),"")) | BV5: =IF(49=0,TEXT(BV7,"yyyy"),IF(YEAR(BV7)<>YEAR(BU7),TEXT(BV7,"yyyy"),"")) | BW5: =IF(50=0,TEXT(BW7,"yyyy"),IF(YEAR(BW7)<>YEAR(BV7),TEXT(BW7,"yyyy"),"")) | BX5: =IF(51=0,TEXT(BX7,"yyyy"),IF(YEAR(BX7)<>YEAR(BW7),TEXT(BX7,"yyyy"),""))
Y6: =TEXT(Y7,"mmm") -> Oct | Z6: =IF(MONTH(Z7)<>MONTH(Y7),TEXT(Z7,"mmm"),"") | AA6: =IF(MONTH(AA7)<>MONTH(Z7),TEXT(AA7,"mmm"),"") | AB6: =IF(MONTH(AB7)<>MONTH(AA7),TEXT(AB7,"mmm"),"") -> Nov | AC6: =IF(MONTH(AC7)<>MONTH(AB7),TEXT(AC7,"mmm"),"") | AD6: =IF(MONTH(AD7)<>MONTH(AC7),TEXT(AD7,"mmm"),"") | AE6: =IF(MONTH(AE7)<>MONTH(AD7),TEXT(AE7,"mmm"),"") | AF6: =IF(MONTH(AF7)<>MONTH(AE7),TEXT(AF7,"mmm"),"") | AG6: =IF(MONTH(AG7)<>MONTH(AF7),TEXT(AG7,"mmm"),"") -> Dec | ... BX6: =IF(MONTH(BX7)<>MONTH(BW7),TEXT(BX7,"mmm"),"") -> Oct
B7: ID | C7: FASE / ACTIVIDAD | D7: Tipo | E7: Responsable | F7: Frente vinculado (presupuesto) | G7: Pred. | H7: Inicio fijo (opcional) | I7: Días | J7: Inicio | K7: Fin | L7: Inicio REAL | M7: Fin REAL | N7: % manual | O7: Avance | P7: Estado | Q7: Días atraso | Y7: =IF(COUNT($J$8:$J$36)=0,TODAY(),MIN($J$8:$J$36))-WEEKDAY(IF(COUNT($J$8:$J$36)=0,TODAY(),MIN($J$8:$J$36)),2)+1 -> 46307 | Z7: =Y7+7 -> 46314 | AA7: =Z7+7 -> 46321 | AB7: =AA7+7 -> 46328 | AC7: =AB7+7 -> 46335 | AD7: =AC7+7 -> 46342 | AE7: =AD7+7 -> 46349 | AF7: =AE7+7 -> 46356 | AG7: =AF7+7 -> 46363 | ... BX7: =BW7+7 -> 46664
B8: ="F"&R8 -> F1 | C8: INICIO Y PLANEACIÓN | D8: Fase | I8: =IF(OR(J8="",K8=""),"",K8-J8+1) -> 6 | J8: =IFERROR(1/(1/_xlfn.MINIFS($S$8:$S$36,$R$8:$R$36,R8)),"") -> 46312 | K8: =IFERROR(1/(1/_xlfn.MAXIFS($T$8:$T$36,$R$8:$R$36,R8)),"") -> 46317 | O8: =IFERROR(SUMIFS($V$8:$V$36,$R$8:$R$36,R8)/SUMIFS($U$8:$U$36,$R$8:$R$36,R8),"") -> 0 | P8: =IF(COUNTIFS($R$8:$R$36,R8,$U$8:$U$36,">0")=0,"",IF(COUNTIFS($R$8:$R$36,R8,$W$8:$W$36,"Atrasada")+COUNTIFS($R$8:$R$36,R8,$W$8:$W$36,"Vencido")>0,"Con atraso",IF(N(O8)>=1,"Terminada",IF(N(O8)>0,"En curso","Por iniciar")))) -> Por iniciar | Q8: =IF(N(_xlfn.MAXIFS($X$8:$X$36,$R$8:$R$36,R8))>0,_xlfn.MAXIFS($X$8:$X$36,$R$8:$R$36,R8),"") | R8: =COUNTIF($D$8:D8,"Fase") -> 1
B9: 1 | C9: Firma de contrato / orden de compra | D9: Hito | E9: Gerencia | I9: 0 | J9: =IF(C9="","",IF(L9<>"",L9,IF(H9<>"",H9,IF(G9<>"",IFERROR(INDEX($T$8:$T$36,MATCH(G9,$B$8:$B$36,0))+IF(D9="Hito",0,1),IF(n_FInicio="",TODAY(),n_FInicio)),IF(n_FInicio="",TODAY(),n_FInicio))))) -> 46312 | K9: =IF(C9="","",IF(M9<>"",M9,IF(D9="Hito",J9,J9+MAX(N(I9),1)-1))) -> 46312 | O9: =IF(C9="","",IF(N9<>"",N9,IF(M9<>"",1,IF(F9="",0,IF(D9="Instalación",MIN(1,IFERROR(SUMIFS('CORTES CLIENTE'!$O$20:$O$219,PRESUPUESTO!$V$7:$V$206,F9)/SUMIFS(PRESUPUESTO!$G$7:$G$206,PRESUPUESTO!$V$7:$V$206,F9),0)),IF(D9="Compra",MIN(1,IFERROR(SUMIFS('CONTROL DE MATERIALES'!$U$11:$U$210,PRESUPUESTO!$V$7:$V$206,F9)/SUMIFS('CONTROL DE MATERIALES'!$V$11:$V$210,PRESUPUESTO!$V$7:$V$206,F9),0)),0)))))) -> 0 | P9: =IF(C9="","",IF(D9="Hito",IF(O9>=1,"Cumplido",IF(TODAY()>K9,"Vencido","Pendiente")),IF(O9>=1,"Terminada",IF(TODAY()>K9,"Atrasada",IF(OR(O9>0,L9<>""),"En curso",IF(TODAY()>=J9,"Debe iniciar","Por iniciar")))))) -> Pendiente | Q9: =IF(OR(C9="",N(O9)>=1),"",IF(TODAY()>K9,TODAY()-K9,0)) -> 0 | R9: =COUNTIF($D$8:D9,"Fase") -> 1 | S9: =IF(C9="","",J9) -> 46312 | T9: =IF(C9="","",K9) -> 46312 | U9: =IF(C9="","",MAX(N(I9),1)) -> 1 | V9: =IF(C9="","",U9*N(O9)) -> 0 | W9: =P9 -> Pendiente | X9: =IF(Q9="","",N(Q9)) -> 0 | Y9: =IF(AND($D9="Hito",ISNUMBER($K9)),IF(AND($K9>=Y$7,$K9<Y$7+7),"◆",""),"") -> ◆ | Z9: =IF(AND($D9="Hito",ISNUMBER($K9)),IF(AND($K9>=Z$7,$K9<Z$7+7),"◆",""),"") | AA9: =IF(AND($D9="Hito",ISNUMBER($K9)),IF(AND($K9>=AA$7,$K9<AA$7+7),"◆",""),"") | AB9: =IF(AND($D9="Hito",ISNUMBER($K9)),IF(AND($K9>=AB$7,$K9<AB$7+7),"◆",""),"") | AC9: =IF(AND($D9="Hito",ISNUMBER($K9)),IF(AND($K9>=AC$7,$K9<AC$7+7),"◆",""),"") | AD9: =IF(AND($D9="Hito",ISNUMBER($K9)),IF(AND($K9>=AD$7,$K9<AD$7+7),"◆",""),"") | AE9: =IF(AND($D9="Hito",ISNUMBER($K9)),IF(AND($K9>=AE$7,$K9<AE$7+7),"◆",""),"") | AF9: =IF(AND($D9="Hito",ISNUMBER($K9)),IF(AND($K9>=AF$7,$K9<AF$7+7),"◆",""),"") | ... BX9: =IF(AND($D9="Hito",ISNUMBER($K9)),IF(AND($K9>=BX$7,$K9<BX$7+7),"◆",""),"")
B10: 2 | C10: Socialización del proyecto con el cliente | D10: Hito | E10: Dir. proyectos | G10: 1 | I10: 0 | J10: =IF(C10="","",IF(L10<>"",L10,IF(H10<>"",H10,IF(G10<>"",IFERROR(INDEX($T$8:$T$36,MATCH(G10,$B$8:$B$36,0))+IF(D10="Hito",0,1),IF(n_FInicio="",TODAY(),n_FInicio)),IF(n_FInicio="",TODAY(),n_FInicio))))) -> 46312 | K10: =IF(C10="","",IF(M10<>"",M10,IF(D10="Hito",J10,J10+MAX(N(I10),1)-1))) -> 46312 | O10: =IF(C10="","",IF(N10<>"",N10,IF(M10<>"",1,IF(F10="",0,IF(D10="Instalación",MIN(1,IFERROR(SUMIFS('CORTES CLIENTE'!$O$20:$O$219,PRESUPUESTO!$V$7:$V$206,F10)/SUMIFS(PRESUPUESTO!$G$7:$G$206,PRESUPUESTO!$V$7:$V$206,F10),0)),IF(D10="Compra",MIN(1,IFERROR(SUMIFS('CONTROL DE MATERIALES'!$U$11:$U$210,PRESUPUESTO!$V$7:$V$206,F10)/SUMIFS('CONTROL DE MATERIALES'!$V$11:$V$210,PRESUPUESTO!$V$7:$V$206,F10),0)),0)))))) -> 0 | P10: =IF(C10="","",IF(D10="Hito",IF(O10>=1,"Cumplido",IF(TODAY()>K10,"Vencido","Pendiente")),IF(O10>=1,"Terminada",IF(TODAY()>K10,"Atrasada",IF(OR(O10>0,L10<>""),"En curso",IF(TODAY()>=J10,"Debe iniciar","Por iniciar")))))) -> Pendiente | Q10: =IF(OR(C10="",N(O10)>=1),"",IF(TODAY()>K10,TODAY()-K10,0)) -> 0 | R10: =COUNTIF($D$8:D10,"Fase") -> 1 | S10: =IF(C10="","",J10) -> 46312 | T10: =IF(C10="","",K10) -> 46312 | U10: =IF(C10="","",MAX(N(I10),1)) -> 1 | V10: =IF(C10="","",U10*N(O10)) -> 0 | W10: =P10 -> Pendiente | X10: =IF(Q10="","",N(Q10)) -> 0 | Y10: =IF(AND($D10="Hito",ISNUMBER($K10)),IF(AND($K10>=Y$7,$K10<Y$7+7),"◆",""),"") -> ◆ | Z10: =IF(AND($D10="Hito",ISNUMBER($K10)),IF(AND($K10>=Z$7,$K10<Z$7+7),"◆",""),"") | AA10: =IF(AND($D10="Hito",ISNUMBER($K10)),IF(AND($K10>=AA$7,$K10<AA$7+7),"◆",""),"") | AB10: =IF(AND($D10="Hito",ISNUMBER($K10)),IF(AND($K10>=AB$7,$K10<AB$7+7),"◆",""),"") | AC10: =IF(AND($D10="Hito",ISNUMBER($K10)),IF(AND($K10>=AC$7,$K10<AC$7+7),"◆",""),"") | AD10: =IF(AND($D10="Hito",ISNUMBER($K10)),IF(AND($K10>=AD$7,$K10<AD$7+7),"◆",""),"") | AE10: =IF(AND($D10="Hito",ISNUMBER($K10)),IF(AND($K10>=AE$7,$K10<AE$7+7),"◆",""),"") | AF10: =IF(AND($D10="Hito",ISNUMBER($K10)),IF(AND($K10>=AF$7,$K10<AF$7+7),"◆",""),"") | ... BX10: =IF(AND($D10="Hito",ISNUMBER($K10)),IF(AND($K10>=BX$7,$K10<BX$7+7),"◆",""),"")
B11: 3 | C11: Planeación, programación y pedidos iniciales | D11: Gestión | E11: Dir. proyectos | G11: 2 | I11: 5 | J11: =IF(C11="","",IF(L11<>"",L11,IF(H11<>"",H11,IF(G11<>"",IFERROR(INDEX($T$8:$T$36,MATCH(G11,$B$8:$B$36,0))+IF(D11="Hito",0,1),IF(n_FInicio="",TODAY(),n_FInicio)),IF(n_FInicio="",TODAY(),n_FInicio))))) -> 46313 | K11: =IF(C11="","",IF(M11<>"",M11,IF(D11="Hito",J11,J11+MAX(N(I11),1)-1))) -> 46317 | O11: =IF(C11="","",IF(N11<>"",N11,IF(M11<>"",1,IF(F11="",0,IF(D11="Instalación",MIN(1,IFERROR(SUMIFS('CORTES CLIENTE'!$O$20:$O$219,PRESUPUESTO!$V$7:$V$206,F11)/SUMIFS(PRESUPUESTO!$G$7:$G$206,PRESUPUESTO!$V$7:$V$206,F11),0)),IF(D11="Compra",MIN(1,IFERROR(SUMIFS('CONTROL DE MATERIALES'!$U$11:$U$210,PRESUPUESTO!$V$7:$V$206,F11)/SUMIFS('CONTROL DE MATERIALES'!$V$11:$V$210,PRESUPUESTO!$V$7:$V$206,F11),0)),0)))))) -> 0 | P11: =IF(C11="","",IF(D11="Hito",IF(O11>=1,"Cumplido",IF(TODAY()>K11,"Vencido","Pendiente")),IF(O11>=1,"Terminada",IF(TODAY()>K11,"Atrasada",IF(OR(O11>0,L11<>""),"En curso",IF(TODAY()>=J11,"Debe iniciar","Por iniciar")))))) -> Por iniciar | Q11: =IF(OR(C11="",N(O11)>=1),"",IF(TODAY()>K11,TODAY()-K11,0)) -> 0 | R11: =COUNTIF($D$8:D11,"Fase") -> 1 | S11: =IF(C11="","",J11) -> 46313 | T11: =IF(C11="","",K11) -> 46317 | U11: =IF(C11="","",MAX(N(I11),1)) -> 5 | V11: =IF(C11="","",U11*N(O11)) -> 0 | W11: =P11 -> Por iniciar | X11: =IF(Q11="","",N(Q11)) -> 0 | Y11: =IF(AND($D11="Hito",ISNUMBER($K11)),IF(AND($K11>=Y$7,$K11<Y$7+7),"◆",""),"") | Z11: =IF(AND($D11="Hito",ISNUMBER($K11)),IF(AND($K11>=Z$7,$K11<Z$7+7),"◆",""),"") | AA11: =IF(AND($D11="Hito",ISNUMBER($K11)),IF(AND($K11>=AA$7,$K11<AA$7+7),"◆",""),"") | AB11: =IF(AND($D11="Hito",ISNUMBER($K11)),IF(AND($K11>=AB$7,$K11<AB$7+7),"◆",""),"") | AC11: =IF(AND($D11="Hito",ISNUMBER($K11)),IF(AND($K11>=AC$7,$K11<AC$7+7),"◆",""),"") | AD11: =IF(AND($D11="Hito",ISNUMBER($K11)),IF(AND($K11>=AD$7,$K11<AD$7+7),"◆",""),"") | AE11: =IF(AND($D11="Hito",ISNUMBER($K11)),IF(AND($K11>=AE$7,$K11<AE$7+7),"◆",""),"") | AF11: =IF(AND($D11="Hito",ISNUMBER($K11)),IF(AND($K11>=AF$7,$K11<AF$7+7),"◆",""),"") | ... BX11: =IF(AND($D11="Hito",ISNUMBER($K11)),IF(AND($K11>=BX$7,$K11<BX$7+7),"◆",""),"")
B12: 4 | C12: Acta de inicio de obra | D12: Hito | E12: Dir. proyectos | G12: 3 | I12: 0 | J12: =IF(C12="","",IF(L12<>"",L12,IF(H12<>"",H12,IF(G12<>"",IFERROR(INDEX($T$8:$T$36,MATCH(G12,$B$8:$B$36,0))+IF(D12="Hito",0,1),IF(n_FInicio="",TODAY(),n_FInicio)),IF(n_FInicio="",TODAY(),n_FInicio))))) -> 46317 | K12: =IF(C12="","",IF(M12<>"",M12,IF(D12="Hito",J12,J12+MAX(N(I12),1)-1))) -> 46317 | O12: =IF(C12="","",IF(N12<>"",N12,IF(M12<>"",1,IF(F12="",0,IF(D12="Instalación",MIN(1,IFERROR(SUMIFS('CORTES CLIENTE'!$O$20:$O$219,PRESUPUESTO!$V$7:$V$206,F12)/SUMIFS(PRESUPUESTO!$G$7:$G$206,PRESUPUESTO!$V$7:$V$206,F12),0)),IF(D12="Compra",MIN(1,IFERROR(SUMIFS('CONTROL DE MATERIALES'!$U$11:$U$210,PRESUPUESTO!$V$7:$V$206,F12)/SUMIFS('CONTROL DE MATERIALES'!$V$11:$V$210,PRESUPUESTO!$V$7:$V$206,F12),0)),0)))))) -> 0 | P12: =IF(C12="","",IF(D12="Hito",IF(O12>=1,"Cumplido",IF(TODAY()>K12,"Vencido","Pendiente")),IF(O12>=1,"Terminada",IF(TODAY()>K12,"Atrasada",IF(OR(O12>0,L12<>""),"En curso",IF(TODAY()>=J12,"Debe iniciar","Por iniciar")))))) -> Pendiente | Q12: =IF(OR(C12="",N(O12)>=1),"",IF(TODAY()>K12,TODAY()-K12,0)) -> 0 | R12: =COUNTIF($D$8:D12,"Fase") -> 1 | S12: =IF(C12="","",J12) -> 46317 | T12: =IF(C12="","",K12) -> 46317 | U12: =IF(C12="","",MAX(N(I12),1)) -> 1 | V12: =IF(C12="","",U12*N(O12)) -> 0 | W12: =P12 -> Pendiente | X12: =IF(Q12="","",N(Q12)) -> 0 | Y12: =IF(AND($D12="Hito",ISNUMBER($K12)),IF(AND($K12>=Y$7,$K12<Y$7+7),"◆",""),"") | Z12: =IF(AND($D12="Hito",ISNUMBER($K12)),IF(AND($K12>=Z$7,$K12<Z$7+7),"◆",""),"") -> ◆ | AA12: =IF(AND($D12="Hito",ISNUMBER($K12)),IF(AND($K12>=AA$7,$K12<AA$7+7),"◆",""),"") | AB12: =IF(AND($D12="Hito",ISNUMBER($K12)),IF(AND($K12>=AB$7,$K12<AB$7+7),"◆",""),"") | AC12: =IF(AND($D12="Hito",ISNUMBER($K12)),IF(AND($K12>=AC$7,$K12<AC$7+7),"◆",""),"") | AD12: =IF(AND($D12="Hito",ISNUMBER($K12)),IF(AND($K12>=AD$7,$K12<AD$7+7),"◆",""),"") | AE12: =IF(AND($D12="Hito",ISNUMBER($K12)),IF(AND($K12>=AE$7,$K12<AE$7+7),"◆",""),"") | AF12: =IF(AND($D12="Hito",ISNUMBER($K12)),IF(AND($K12>=AF$7,$K12<AF$7+7),"◆",""),"") | ... BX12: =IF(AND($D12="Hito",ISNUMBER($K12)),IF(AND($K12>=BX$7,$K12<BX$7+7),"◆",""),"")
B13: ="F"&R13 -> F2 | C13: FRENTE 1 (cambie el nombre) | D13: Fase | I13: =IF(OR(J13="",K13=""),"",K13-J13+1) -> 28 | J13: =IFERROR(1/(1/_xlfn.MINIFS($S$8:$S$36,$R$8:$R$36,R13)),"") -> 46318 | K13: =IFERROR(1/(1/_xlfn.MAXIFS($T$8:$T$36,$R$8:$R$36,R13)),"") -> 46345 | O13: =IFERROR(SUMIFS($V$8:$V$36,$R$8:$R$36,R13)/SUMIFS($U$8:$U$36,$R$8:$R$36,R13),"") -> 0 | P13: =IF(COUNTIFS($R$8:$R$36,R13,$U$8:$U$36,">0")=0,"",IF(COUNTIFS($R$8:$R$36,R13,$W$8:$W$36,"Atrasada")+COUNTIFS($R$8:$R$36,R13,$W$8:$W$36,"Vencido")>0,"Con atraso",IF(N(O13)>=1,"Terminada",IF(N(O13)>0,"En curso","Por iniciar")))) -> Por iniciar | Q13: =IF(N(_xlfn.MAXIFS($X$8:$X$36,$R$8:$R$36,R13))>0,_xlfn.MAXIFS($X$8:$X$36,$R$8:$R$36,R13),"") | R13: =COUNTIF($D$8:D13,"Fase") -> 2
B14: 5 | C14: Compra materiales — lote 1 | D14: Compra | E14: Compras | G14: 4 | I14: 10 | J14: =IF(C14="","",IF(L14<>"",L14,IF(H14<>"",H14,IF(G14<>"",IFERROR(INDEX($T$8:$T$36,MATCH(G14,$B$8:$B$36,0))+IF(D14="Hito",0,1),IF(n_FInicio="",TODAY(),n_FInicio)),IF(n_FInicio="",TODAY(),n_FInicio))))) -> 46318 | K14: =IF(C14="","",IF(M14<>"",M14,IF(D14="Hito",J14,J14+MAX(N(I14),1)-1))) -> 46327 | O14: =IF(C14="","",IF(N14<>"",N14,IF(M14<>"",1,IF(F14="",0,IF(D14="Instalación",MIN(1,IFERROR(SUMIFS('CORTES CLIENTE'!$O$20:$O$219,PRESUPUESTO!$V$7:$V$206,F14)/SUMIFS(PRESUPUESTO!$G$7:$G$206,PRESUPUESTO!$V$7:$V$206,F14),0)),IF(D14="Compra",MIN(1,IFERROR(SUMIFS('CONTROL DE MATERIALES'!$U$11:$U$210,PRESUPUESTO!$V$7:$V$206,F14)/SUMIFS('CONTROL DE MATERIALES'!$V$11:$V$210,PRESUPUESTO!$V$7:$V$206,F14),0)),0)))))) -> 0 | P14: =IF(C14="","",IF(D14="Hito",IF(O14>=1,"Cumplido",IF(TODAY()>K14,"Vencido","Pendiente")),IF(O14>=1,"Terminada",IF(TODAY()>K14,"Atrasada",IF(OR(O14>0,L14<>""),"En curso",IF(TODAY()>=J14,"Debe iniciar","Por iniciar")))))) -> Por iniciar | Q14: =IF(OR(C14="",N(O14)>=1),"",IF(TODAY()>K14,TODAY()-K14,0)) -> 0 | R14: =COUNTIF($D$8:D14,"Fase") -> 2 | S14: =IF(C14="","",J14) -> 46318 | T14: =IF(C14="","",K14) -> 46327 | U14: =IF(C14="","",MAX(N(I14),1)) -> 10 | V14: =IF(C14="","",U14*N(O14)) -> 0 | W14: =P14 -> Por iniciar | X14: =IF(Q14="","",N(Q14)) -> 0 | Y14: =IF(AND($D14="Hito",ISNUMBER($K14)),IF(AND($K14>=Y$7,$K14<Y$7+7),"◆",""),"") | Z14: =IF(AND($D14="Hito",ISNUMBER($K14)),IF(AND($K14>=Z$7,$K14<Z$7+7),"◆",""),"") | AA14: =IF(AND($D14="Hito",ISNUMBER($K14)),IF(AND($K14>=AA$7,$K14<AA$7+7),"◆",""),"") | AB14: =IF(AND($D14="Hito",ISNUMBER($K14)),IF(AND($K14>=AB$7,$K14<AB$7+7),"◆",""),"") | AC14: =IF(AND($D14="Hito",ISNUMBER($K14)),IF(AND($K14>=AC$7,$K14<AC$7+7),"◆",""),"") | AD14: =IF(AND($D14="Hito",ISNUMBER($K14)),IF(AND($K14>=AD$7,$K14<AD$7+7),"◆",""),"") | AE14: =IF(AND($D14="Hito",ISNUMBER($K14)),IF(AND($K14>=AE$7,$K14<AE$7+7),"◆",""),"") | AF14: =IF(AND($D14="Hito",ISNUMBER($K14)),IF(AND($K14>=AF$7,$K14<AF$7+7),"◆",""),"") | ... BX14: =IF(AND($D14="Hito",ISNUMBER($K14)),IF(AND($K14>=BX$7,$K14<BX$7+7),"◆",""),"")
B15: 6 | C15: Instalación | D15: Instalación | E15: Contratista | G15: 5 | I15: 15 | J15: =IF(C15="","",IF(L15<>"",L15,IF(H15<>"",H15,IF(G15<>"",IFERROR(INDEX($T$8:$T$36,MATCH(G15,$B$8:$B$36,0))+IF(D15="Hito",0,1),IF(n_FInicio="",TODAY(),n_FInicio)),IF(n_FInicio="",TODAY(),n_FInicio))))) -> 46328 | K15: =IF(C15="","",IF(M15<>"",M15,IF(D15="Hito",J15,J15+MAX(N(I15),1)-1))) -> 46342 | O15: =IF(C15="","",IF(N15<>"",N15,IF(M15<>"",1,IF(F15="",0,IF(D15="Instalación",MIN(1,IFERROR(SUMIFS('CORTES CLIENTE'!$O$20:$O$219,PRESUPUESTO!$V$7:$V$206,F15)/SUMIFS(PRESUPUESTO!$G$7:$G$206,PRESUPUESTO!$V$7:$V$206,F15),0)),IF(D15="Compra",MIN(1,IFERROR(SUMIFS('CONTROL DE MATERIALES'!$U$11:$U$210,PRESUPUESTO!$V$7:$V$206,F15)/SUMIFS('CONTROL DE MATERIALES'!$V$11:$V$210,PRESUPUESTO!$V$7:$V$206,F15),0)),0)))))) -> 0 | P15: =IF(C15="","",IF(D15="Hito",IF(O15>=1,"Cumplido",IF(TODAY()>K15,"Vencido","Pendiente")),IF(O15>=1,"Terminada",IF(TODAY()>K15,"Atrasada",IF(OR(O15>0,L15<>""),"En curso",IF(TODAY()>=J15,"Debe iniciar","Por iniciar")))))) -> Por iniciar | Q15: =IF(OR(C15="",N(O15)>=1),"",IF(TODAY()>K15,TODAY()-K15,0)) -> 0 | R15: =COUNTIF($D$8:D15,"Fase") -> 2 | S15: =IF(C15="","",J15) -> 46328 | T15: =IF(C15="","",K15) -> 46342 | U15: =IF(C15="","",MAX(N(I15),1)) -> 15 | V15: =IF(C15="","",U15*N(O15)) -> 0 | W15: =P15 -> Por iniciar | X15: =IF(Q15="","",N(Q15)) -> 0 | Y15: =IF(AND($D15="Hito",ISNUMBER($K15)),IF(AND($K15>=Y$7,$K15<Y$7+7),"◆",""),"") | Z15: =IF(AND($D15="Hito",ISNUMBER($K15)),IF(AND($K15>=Z$7,$K15<Z$7+7),"◆",""),"") | AA15: =IF(AND($D15="Hito",ISNUMBER($K15)),IF(AND($K15>=AA$7,$K15<AA$7+7),"◆",""),"") | AB15: =IF(AND($D15="Hito",ISNUMBER($K15)),IF(AND($K15>=AB$7,$K15<AB$7+7),"◆",""),"") | AC15: =IF(AND($D15="Hito",ISNUMBER($K15)),IF(AND($K15>=AC$7,$K15<AC$7+7),"◆",""),"") | AD15: =IF(AND($D15="Hito",ISNUMBER($K15)),IF(AND($K15>=AD$7,$K15<AD$7+7),"◆",""),"") | AE15: =IF(AND($D15="Hito",ISNUMBER($K15)),IF(AND($K15>=AE$7,$K15<AE$7+7),"◆",""),"") | AF15: =IF(AND($D15="Hito",ISNUMBER($K15)),IF(AND($K15>=AF$7,$K15<AF$7+7),"◆",""),"") | ... BX15: =IF(AND($D15="Hito",ISNUMBER($K15)),IF(AND($K15>=BX$7,$K15<BX$7+7),"◆",""),"")
B16: 7 | C16: Pruebas / certificación | D16: Pruebas | E16: Técnico | G16: 6 | I16: 3 | J16: =IF(C16="","",IF(L16<>"",L16,IF(H16<>"",H16,IF(G16<>"",IFERROR(INDEX($T$8:$T$36,MATCH(G16,$B$8:$B$36,0))+IF(D16="Hito",0,1),IF(n_FInicio="",TODAY(),n_FInicio)),IF(n_FInicio="",TODAY(),n_FInicio))))) -> 46343 | K16: =IF(C16="","",IF(M16<>"",M16,IF(D16="Hito",J16,J16+MAX(N(I16),1)-1))) -> 46345 | O16: =IF(C16="","",IF(N16<>"",N16,IF(M16<>"",1,IF(F16="",0,IF(D16="Instalación",MIN(1,IFERROR(SUMIFS('CORTES CLIENTE'!$O$20:$O$219,PRESUPUESTO!$V$7:$V$206,F16)/SUMIFS(PRESUPUESTO!$G$7:$G$206,PRESUPUESTO!$V$7:$V$206,F16),0)),IF(D16="Compra",MIN(1,IFERROR(SUMIFS('CONTROL DE MATERIALES'!$U$11:$U$210,PRESUPUESTO!$V$7:$V$206,F16)/SUMIFS('CONTROL DE MATERIALES'!$V$11:$V$210,PRESUPUESTO!$V$7:$V$206,F16),0)),0)))))) -> 0 | P16: =IF(C16="","",IF(D16="Hito",IF(O16>=1,"Cumplido",IF(TODAY()>K16,"Vencido","Pendiente")),IF(O16>=1,"Terminada",IF(TODAY()>K16,"Atrasada",IF(OR(O16>0,L16<>""),"En curso",IF(TODAY()>=J16,"Debe iniciar","Por iniciar")))))) -> Por iniciar | Q16: =IF(OR(C16="",N(O16)>=1),"",IF(TODAY()>K16,TODAY()-K16,0)) -> 0 | R16: =COUNTIF($D$8:D16,"Fase") -> 2 | S16: =IF(C16="","",J16) -> 46343 | T16: =IF(C16="","",K16) -> 46345 | U16: =IF(C16="","",MAX(N(I16),1)) -> 3 | V16: =IF(C16="","",U16*N(O16)) -> 0 | W16: =P16 -> Por iniciar | X16: =IF(Q16="","",N(Q16)) -> 0 | Y16: =IF(AND($D16="Hito",ISNUMBER($K16)),IF(AND($K16>=Y$7,$K16<Y$7+7),"◆",""),"") | Z16: =IF(AND($D16="Hito",ISNUMBER($K16)),IF(AND($K16>=Z$7,$K16<Z$7+7),"◆",""),"") | AA16: =IF(AND($D16="Hito",ISNUMBER($K16)),IF(AND($K16>=AA$7,$K16<AA$7+7),"◆",""),"") | AB16: =IF(AND($D16="Hito",ISNUMBER($K16)),IF(AND($K16>=AB$7,$K16<AB$7+7),"◆",""),"") | AC16: =IF(AND($D16="Hito",ISNUMBER($K16)),IF(AND($K16>=AC$7,$K16<AC$7+7),"◆",""),"") | AD16: =IF(AND($D16="Hito",ISNUMBER($K16)),IF(AND($K16>=AD$7,$K16<AD$7+7),"◆",""),"") | AE16: =IF(AND($D16="Hito",ISNUMBER($K16)),IF(AND($K16>=AE$7,$K16<AE$7+7),"◆",""),"") | AF16: =IF(AND($D16="Hito",ISNUMBER($K16)),IF(AND($K16>=AF$7,$K16<AF$7+7),"◆",""),"") | ... BX16: =IF(AND($D16="Hito",ISNUMBER($K16)),IF(AND($K16>=BX$7,$K16<BX$7+7),"◆",""),"")
J17: =IF(C17="","",IF(L17<>"",L17,IF(H17<>"",H17,IF(G17<>"",IFERROR(INDEX($T$8:$T$36,MATCH(G17,$B$8:$B$36,0))+IF(D17="Hito",0,1),IF(n_FInicio="",TODAY(),n_FInicio)),IF(n_FInicio="",TODAY(),n_FInicio))))) | K17: =IF(C17="","",IF(M17<>"",M17,IF(D17="Hito",J17,J17+MAX(N(I17),1)-1))) | O17: =IF(C17="","",IF(N17<>"",N17,IF(M17<>"",1,IF(F17="",0,IF(D17="Instalación",MIN(1,IFERROR(SUMIFS('CORTES CLIENTE'!$O$20:$O$219,PRESUPUESTO!$V$7:$V$206,F17)/SUMIFS(PRESUPUESTO!$G$7:$G$206,PRESUPUESTO!$V$7:$V$206,F17),0)),IF(D17="Compra",MIN(1,IFERROR(SUMIFS('CONTROL DE MATERIALES'!$U$11:$U$210,PRESUPUESTO!$V$7:$V$206,F17)/SUMIFS('CONTROL DE MATERIALES'!$V$11:$V$210,PRESUPUESTO!$V$7:$V$206,F17),0)),0)))))) | P17: =IF(C17="","",IF(D17="Hito",IF(O17>=1,"Cumplido",IF(TODAY()>K17,"Vencido","Pendiente")),IF(O17>=1,"Terminada",IF(TODAY()>K17,"Atrasada",IF(OR(O17>0,L17<>""),"En curso",IF(TODAY()>=J17,"Debe iniciar","Por iniciar")))))) | Q17: =IF(OR(C17="",N(O17)>=1),"",IF(TODAY()>K17,TODAY()-K17,0)) | R17: =COUNTIF($D$8:D17,"Fase") -> 2 | S17: =IF(C17="","",J17) | T17: =IF(C17="","",K17) | U17: =IF(C17="","",MAX(N(I17),1)) | V17: =IF(C17="","",U17*N(O17)) | W17: =P17 | X17: =IF(Q17="","",N(Q17)) | Y17: =IF(AND($D17="Hito",ISNUMBER($K17)),IF(AND($K17>=Y$7,$K17<Y$7+7),"◆",""),"") | Z17: =IF(AND($D17="Hito",ISNUMBER($K17)),IF(AND($K17>=Z$7,$K17<Z$7+7),"◆",""),"") | AA17: =IF(AND($D17="Hito",ISNUMBER($K17)),IF(AND($K17>=AA$7,$K17<AA$7+7),"◆",""),"") | AB17: =IF(AND($D17="Hito",ISNUMBER($K17)),IF(AND($K17>=AB$7,$K17<AB$7+7),"◆",""),"") | AC17: =IF(AND($D17="Hito",ISNUMBER($K17)),IF(AND($K17>=AC$7,$K17<AC$7+7),"◆",""),"") | AD17: =IF(AND($D17="Hito",ISNUMBER($K17)),IF(AND($K17>=AD$7,$K17<AD$7+7),"◆",""),"") | AE17: =IF(AND($D17="Hito",ISNUMBER($K17)),IF(AND($K17>=AE$7,$K17<AE$7+7),"◆",""),"") | AF17: =IF(AND($D17="Hito",ISNUMBER($K17)),IF(AND($K17>=AF$7,$K17<AF$7+7),"◆",""),"") | ... BX17: =IF(AND($D17="Hito",ISNUMBER($K17)),IF(AND($K17>=BX$7,$K17<BX$7+7),"◆",""),"")
J18: =IF(C18="","",IF(L18<>"",L18,IF(H18<>"",H18,IF(G18<>"",IFERROR(INDEX($T$8:$T$36,MATCH(G18,$B$8:$B$36,0))+IF(D18="Hito",0,1),IF(n_FInicio="",TODAY(),n_FInicio)),IF(n_FInicio="",TODAY(),n_FInicio))))) | K18: =IF(C18="","",IF(M18<>"",M18,IF(D18="Hito",J18,J18+MAX(N(I18),1)-1))) | O18: =IF(C18="","",IF(N18<>"",N18,IF(M18<>"",1,IF(F18="",0,IF(D18="Instalación",MIN(1,IFERROR(SUMIFS('CORTES CLIENTE'!$O$20:$O$219,PRESUPUESTO!$V$7:$V$206,F18)/SUMIFS(PRESUPUESTO!$G$7:$G$206,PRESUPUESTO!$V$7:$V$206,F18),0)),IF(D18="Compra",MIN(1,IFERROR(SUMIFS('CONTROL DE MATERIALES'!$U$11:$U$210,PRESUPUESTO!$V$7:$V$206,F18)/SUMIFS('CONTROL DE MATERIALES'!$V$11:$V$210,PRESUPUESTO!$V$7:$V$206,F18),0)),0)))))) | P18: =IF(C18="","",IF(D18="Hito",IF(O18>=1,"Cumplido",IF(TODAY()>K18,"Vencido","Pendiente")),IF(O18>=1,"Terminada",IF(TODAY()>K18,"Atrasada",IF(OR(O18>0,L18<>""),"En curso",IF(TODAY()>=J18,"Debe iniciar","Por iniciar")))))) | Q18: =IF(OR(C18="",N(O18)>=1),"",IF(TODAY()>K18,TODAY()-K18,0)) | R18: =COUNTIF($D$8:D18,"Fase") -> 2 | S18: =IF(C18="","",J18) | T18: =IF(C18="","",K18) | U18: =IF(C18="","",MAX(N(I18),1)) | V18: =IF(C18="","",U18*N(O18)) | W18: =P18 | X18: =IF(Q18="","",N(Q18)) | Y18: =IF(AND($D18="Hito",ISNUMBER($K18)),IF(AND($K18>=Y$7,$K18<Y$7+7),"◆",""),"") | Z18: =IF(AND($D18="Hito",ISNUMBER($K18)),IF(AND($K18>=Z$7,$K18<Z$7+7),"◆",""),"") | AA18: =IF(AND($D18="Hito",ISNUMBER($K18)),IF(AND($K18>=AA$7,$K18<AA$7+7),"◆",""),"") | AB18: =IF(AND($D18="Hito",ISNUMBER($K18)),IF(AND($K18>=AB$7,$K18<AB$7+7),"◆",""),"") | AC18: =IF(AND($D18="Hito",ISNUMBER($K18)),IF(AND($K18>=AC$7,$K18<AC$7+7),"◆",""),"") | AD18: =IF(AND($D18="Hito",ISNUMBER($K18)),IF(AND($K18>=AD$7,$K18<AD$7+7),"◆",""),"") | AE18: =IF(AND($D18="Hito",ISNUMBER($K18)),IF(AND($K18>=AE$7,$K18<AE$7+7),"◆",""),"") | AF18: =IF(AND($D18="Hito",ISNUMBER($K18)),IF(AND($K18>=AF$7,$K18<AF$7+7),"◆",""),"") | ... BX18: =IF(AND($D18="Hito",ISNUMBER($K18)),IF(AND($K18>=BX$7,$K18<BX$7+7),"◆",""),"")
B19: ="F"&R19 -> F3 | C19: FRENTE 2 (cambie el nombre) | D19: Fase | I19: =IF(OR(J19="",K19=""),"",K19-J19+1) -> 28 | J19: =IFERROR(1/(1/_xlfn.MINIFS($S$8:$S$36,$R$8:$R$36,R19)),"") -> 46318 | K19: =IFERROR(1/(1/_xlfn.MAXIFS($T$8:$T$36,$R$8:$R$36,R19)),"") -> 46345 | O19: =IFERROR(SUMIFS($V$8:$V$36,$R$8:$R$36,R19)/SUMIFS($U$8:$U$36,$R$8:$R$36,R19),"") -> 0 | P19: =IF(COUNTIFS($R$8:$R$36,R19,$U$8:$U$36,">0")=0,"",IF(COUNTIFS($R$8:$R$36,R19,$W$8:$W$36,"Atrasada")+COUNTIFS($R$8:$R$36,R19,$W$8:$W$36,"Vencido")>0,"Con atraso",IF(N(O19)>=1,"Terminada",IF(N(O19)>0,"En curso","Por iniciar")))) -> Por iniciar | Q19: =IF(N(_xlfn.MAXIFS($X$8:$X$36,$R$8:$R$36,R19))>0,_xlfn.MAXIFS($X$8:$X$36,$R$8:$R$36,R19),"") | R19: =COUNTIF($D$8:D19,"Fase") -> 3
B20: 8 | C20: Compra materiales — lote 1 | D20: Compra | E20: Compras | G20: 4 | I20: 10 | J20: =IF(C20="","",IF(L20<>"",L20,IF(H20<>"",H20,IF(G20<>"",IFERROR(INDEX($T$8:$T$36,MATCH(G20,$B$8:$B$36,0))+IF(D20="Hito",0,1),IF(n_FInicio="",TODAY(),n_FInicio)),IF(n_FInicio="",TODAY(),n_FInicio))))) -> 46318 | K20: =IF(C20="","",IF(M20<>"",M20,IF(D20="Hito",J20,J20+MAX(N(I20),1)-1))) -> 46327 | O20: =IF(C20="","",IF(N20<>"",N20,IF(M20<>"",1,IF(F20="",0,IF(D20="Instalación",MIN(1,IFERROR(SUMIFS('CORTES CLIENTE'!$O$20:$O$219,PRESUPUESTO!$V$7:$V$206,F20)/SUMIFS(PRESUPUESTO!$G$7:$G$206,PRESUPUESTO!$V$7:$V$206,F20),0)),IF(D20="Compra",MIN(1,IFERROR(SUMIFS('CONTROL DE MATERIALES'!$U$11:$U$210,PRESUPUESTO!$V$7:$V$206,F20)/SUMIFS('CONTROL DE MATERIALES'!$V$11:$V$210,PRESUPUESTO!$V$7:$V$206,F20),0)),0)))))) -> 0 | P20: =IF(C20="","",IF(D20="Hito",IF(O20>=1,"Cumplido",IF(TODAY()>K20,"Vencido","Pendiente")),IF(O20>=1,"Terminada",IF(TODAY()>K20,"Atrasada",IF(OR(O20>0,L20<>""),"En curso",IF(TODAY()>=J20,"Debe iniciar","Por iniciar")))))) -> Por iniciar | Q20: =IF(OR(C20="",N(O20)>=1),"",IF(TODAY()>K20,TODAY()-K20,0)) -> 0 | R20: =COUNTIF($D$8:D20,"Fase") -> 3 | S20: =IF(C20="","",J20) -> 46318 | T20: =IF(C20="","",K20) -> 46327 | U20: =IF(C20="","",MAX(N(I20),1)) -> 10 | V20: =IF(C20="","",U20*N(O20)) -> 0 | W20: =P20 -> Por iniciar | X20: =IF(Q20="","",N(Q20)) -> 0 | Y20: =IF(AND($D20="Hito",ISNUMBER($K20)),IF(AND($K20>=Y$7,$K20<Y$7+7),"◆",""),"") | Z20: =IF(AND($D20="Hito",ISNUMBER($K20)),IF(AND($K20>=Z$7,$K20<Z$7+7),"◆",""),"") | AA20: =IF(AND($D20="Hito",ISNUMBER($K20)),IF(AND($K20>=AA$7,$K20<AA$7+7),"◆",""),"") | AB20: =IF(AND($D20="Hito",ISNUMBER($K20)),IF(AND($K20>=AB$7,$K20<AB$7+7),"◆",""),"") | AC20: =IF(AND($D20="Hito",ISNUMBER($K20)),IF(AND($K20>=AC$7,$K20<AC$7+7),"◆",""),"") | AD20: =IF(AND($D20="Hito",ISNUMBER($K20)),IF(AND($K20>=AD$7,$K20<AD$7+7),"◆",""),"") | AE20: =IF(AND($D20="Hito",ISNUMBER($K20)),IF(AND($K20>=AE$7,$K20<AE$7+7),"◆",""),"") | AF20: =IF(AND($D20="Hito",ISNUMBER($K20)),IF(AND($K20>=AF$7,$K20<AF$7+7),"◆",""),"") | ... BX20: =IF(AND($D20="Hito",ISNUMBER($K20)),IF(AND($K20>=BX$7,$K20<BX$7+7),"◆",""),"")
B21: 9 | C21: Instalación | D21: Instalación | E21: Contratista | G21: 8 | I21: 15 | J21: =IF(C21="","",IF(L21<>"",L21,IF(H21<>"",H21,IF(G21<>"",IFERROR(INDEX($T$8:$T$36,MATCH(G21,$B$8:$B$36,0))+IF(D21="Hito",0,1),IF(n_FInicio="",TODAY(),n_FInicio)),IF(n_FInicio="",TODAY(),n_FInicio))))) -> 46328 | K21: =IF(C21="","",IF(M21<>"",M21,IF(D21="Hito",J21,J21+MAX(N(I21),1)-1))) -> 46342 | O21: =IF(C21="","",IF(N21<>"",N21,IF(M21<>"",1,IF(F21="",0,IF(D21="Instalación",MIN(1,IFERROR(SUMIFS('CORTES CLIENTE'!$O$20:$O$219,PRESUPUESTO!$V$7:$V$206,F21)/SUMIFS(PRESUPUESTO!$G$7:$G$206,PRESUPUESTO!$V$7:$V$206,F21),0)),IF(D21="Compra",MIN(1,IFERROR(SUMIFS('CONTROL DE MATERIALES'!$U$11:$U$210,PRESUPUESTO!$V$7:$V$206,F21)/SUMIFS('CONTROL DE MATERIALES'!$V$11:$V$210,PRESUPUESTO!$V$7:$V$206,F21),0)),0)))))) -> 0 | P21: =IF(C21="","",IF(D21="Hito",IF(O21>=1,"Cumplido",IF(TODAY()>K21,"Vencido","Pendiente")),IF(O21>=1,"Terminada",IF(TODAY()>K21,"Atrasada",IF(OR(O21>0,L21<>""),"En curso",IF(TODAY()>=J21,"Debe iniciar","Por iniciar")))))) -> Por iniciar | Q21: =IF(OR(C21="",N(O21)>=1),"",IF(TODAY()>K21,TODAY()-K21,0)) -> 0 | R21: =COUNTIF($D$8:D21,"Fase") -> 3 | S21: =IF(C21="","",J21) -> 46328 | T21: =IF(C21="","",K21) -> 46342 | U21: =IF(C21="","",MAX(N(I21),1)) -> 15 | V21: =IF(C21="","",U21*N(O21)) -> 0 | W21: =P21 -> Por iniciar | X21: =IF(Q21="","",N(Q21)) -> 0 | Y21: =IF(AND($D21="Hito",ISNUMBER($K21)),IF(AND($K21>=Y$7,$K21<Y$7+7),"◆",""),"") | Z21: =IF(AND($D21="Hito",ISNUMBER($K21)),IF(AND($K21>=Z$7,$K21<Z$7+7),"◆",""),"") | AA21: =IF(AND($D21="Hito",ISNUMBER($K21)),IF(AND($K21>=AA$7,$K21<AA$7+7),"◆",""),"") | AB21: =IF(AND($D21="Hito",ISNUMBER($K21)),IF(AND($K21>=AB$7,$K21<AB$7+7),"◆",""),"") | AC21: =IF(AND($D21="Hito",ISNUMBER($K21)),IF(AND($K21>=AC$7,$K21<AC$7+7),"◆",""),"") | AD21: =IF(AND($D21="Hito",ISNUMBER($K21)),IF(AND($K21>=AD$7,$K21<AD$7+7),"◆",""),"") | AE21: =IF(AND($D21="Hito",ISNUMBER($K21)),IF(AND($K21>=AE$7,$K21<AE$7+7),"◆",""),"") | AF21: =IF(AND($D21="Hito",ISNUMBER($K21)),IF(AND($K21>=AF$7,$K21<AF$7+7),"◆",""),"") | ... BX21: =IF(AND($D21="Hito",ISNUMBER($K21)),IF(AND($K21>=BX$7,$K21<BX$7+7),"◆",""),"")
B22: 10 | C22: Pruebas / certificación | D22: Pruebas | E22: Técnico | G22: 9 | I22: 3 | J22: =IF(C22="","",IF(L22<>"",L22,IF(H22<>"",H22,IF(G22<>"",IFERROR(INDEX($T$8:$T$36,MATCH(G22,$B$8:$B$36,0))+IF(D22="Hito",0,1),IF(n_FInicio="",TODAY(),n_FInicio)),IF(n_FInicio="",TODAY(),n_FInicio))))) -> 46343 | K22: =IF(C22="","",IF(M22<>"",M22,IF(D22="Hito",J22,J22+MAX(N(I22),1)-1))) -> 46345 | O22: =IF(C22="","",IF(N22<>"",N22,IF(M22<>"",1,IF(F22="",0,IF(D22="Instalación",MIN(1,IFERROR(SUMIFS('CORTES CLIENTE'!$O$20:$O$219,PRESUPUESTO!$V$7:$V$206,F22)/SUMIFS(PRESUPUESTO!$G$7:$G$206,PRESUPUESTO!$V$7:$V$206,F22),0)),IF(D22="Compra",MIN(1,IFERROR(SUMIFS('CONTROL DE MATERIALES'!$U$11:$U$210,PRESUPUESTO!$V$7:$V$206,F22)/SUMIFS('CONTROL DE MATERIALES'!$V$11:$V$210,PRESUPUESTO!$V$7:$V$206,F22),0)),0)))))) -> 0 | P22: =IF(C22="","",IF(D22="Hito",IF(O22>=1,"Cumplido",IF(TODAY()>K22,"Vencido","Pendiente")),IF(O22>=1,"Terminada",IF(TODAY()>K22,"Atrasada",IF(OR(O22>0,L22<>""),"En curso",IF(TODAY()>=J22,"Debe iniciar","Por iniciar")))))) -> Por iniciar | Q22: =IF(OR(C22="",N(O22)>=1),"",IF(TODAY()>K22,TODAY()-K22,0)) -> 0 | R22: =COUNTIF($D$8:D22,"Fase") -> 3 | S22: =IF(C22="","",J22) -> 46343 | T22: =IF(C22="","",K22) -> 46345 | U22: =IF(C22="","",MAX(N(I22),1)) -> 3 | V22: =IF(C22="","",U22*N(O22)) -> 0 | W22: =P22 -> Por iniciar | X22: =IF(Q22="","",N(Q22)) -> 0 | Y22: =IF(AND($D22="Hito",ISNUMBER($K22)),IF(AND($K22>=Y$7,$K22<Y$7+7),"◆",""),"") | Z22: =IF(AND($D22="Hito",ISNUMBER($K22)),IF(AND($K22>=Z$7,$K22<Z$7+7),"◆",""),"") | AA22: =IF(AND($D22="Hito",ISNUMBER($K22)),IF(AND($K22>=AA$7,$K22<AA$7+7),"◆",""),"") | AB22: =IF(AND($D22="Hito",ISNUMBER($K22)),IF(AND($K22>=AB$7,$K22<AB$7+7),"◆",""),"") | AC22: =IF(AND($D22="Hito",ISNUMBER($K22)),IF(AND($K22>=AC$7,$K22<AC$7+7),"◆",""),"") | AD22: =IF(AND($D22="Hito",ISNUMBER($K22)),IF(AND($K22>=AD$7,$K22<AD$7+7),"◆",""),"") | AE22: =IF(AND($D22="Hito",ISNUMBER($K22)),IF(AND($K22>=AE$7,$K22<AE$7+7),"◆",""),"") | AF22: =IF(AND($D22="Hito",ISNUMBER($K22)),IF(AND($K22>=AF$7,$K22<AF$7+7),"◆",""),"") | ... BX22: =IF(AND($D22="Hito",ISNUMBER($K22)),IF(AND($K22>=BX$7,$K22<BX$7+7),"◆",""),"")
J23: =IF(C23="","",IF(L23<>"",L23,IF(H23<>"",H23,IF(G23<>"",IFERROR(INDEX($T$8:$T$36,MATCH(G23,$B$8:$B$36,0))+IF(D23="Hito",0,1),IF(n_FInicio="",TODAY(),n_FInicio)),IF(n_FInicio="",TODAY(),n_FInicio))))) | K23: =IF(C23="","",IF(M23<>"",M23,IF(D23="Hito",J23,J23+MAX(N(I23),1)-1))) | O23: =IF(C23="","",IF(N23<>"",N23,IF(M23<>"",1,IF(F23="",0,IF(D23="Instalación",MIN(1,IFERROR(SUMIFS('CORTES CLIENTE'!$O$20:$O$219,PRESUPUESTO!$V$7:$V$206,F23)/SUMIFS(PRESUPUESTO!$G$7:$G$206,PRESUPUESTO!$V$7:$V$206,F23),0)),IF(D23="Compra",MIN(1,IFERROR(SUMIFS('CONTROL DE MATERIALES'!$U$11:$U$210,PRESUPUESTO!$V$7:$V$206,F23)/SUMIFS('CONTROL DE MATERIALES'!$V$11:$V$210,PRESUPUESTO!$V$7:$V$206,F23),0)),0)))))) | P23: =IF(C23="","",IF(D23="Hito",IF(O23>=1,"Cumplido",IF(TODAY()>K23,"Vencido","Pendiente")),IF(O23>=1,"Terminada",IF(TODAY()>K23,"Atrasada",IF(OR(O23>0,L23<>""),"En curso",IF(TODAY()>=J23,"Debe iniciar","Por iniciar")))))) | Q23: =IF(OR(C23="",N(O23)>=1),"",IF(TODAY()>K23,TODAY()-K23,0)) | R23: =COUNTIF($D$8:D23,"Fase") -> 3 | S23: =IF(C23="","",J23) | T23: =IF(C23="","",K23) | U23: =IF(C23="","",MAX(N(I23),1)) | V23: =IF(C23="","",U23*N(O23)) | W23: =P23 | X23: =IF(Q23="","",N(Q23)) | Y23: =IF(AND($D23="Hito",ISNUMBER($K23)),IF(AND($K23>=Y$7,$K23<Y$7+7),"◆",""),"") | Z23: =IF(AND($D23="Hito",ISNUMBER($K23)),IF(AND($K23>=Z$7,$K23<Z$7+7),"◆",""),"") | AA23: =IF(AND($D23="Hito",ISNUMBER($K23)),IF(AND($K23>=AA$7,$K23<AA$7+7),"◆",""),"") | AB23: =IF(AND($D23="Hito",ISNUMBER($K23)),IF(AND($K23>=AB$7,$K23<AB$7+7),"◆",""),"") | AC23: =IF(AND($D23="Hito",ISNUMBER($K23)),IF(AND($K23>=AC$7,$K23<AC$7+7),"◆",""),"") | AD23: =IF(AND($D23="Hito",ISNUMBER($K23)),IF(AND($K23>=AD$7,$K23<AD$7+7),"◆",""),"") | AE23: =IF(AND($D23="Hito",ISNUMBER($K23)),IF(AND($K23>=AE$7,$K23<AE$7+7),"◆",""),"") | AF23: =IF(AND($D23="Hito",ISNUMBER($K23)),IF(AND($K23>=AF$7,$K23<AF$7+7),"◆",""),"") | ... BX23: =IF(AND($D23="Hito",ISNUMBER($K23)),IF(AND($K23>=BX$7,$K23<BX$7+7),"◆",""),"")
J24: =IF(C24="","",IF(L24<>"",L24,IF(H24<>"",H24,IF(G24<>"",IFERROR(INDEX($T$8:$T$36,MATCH(G24,$B$8:$B$36,0))+IF(D24="Hito",0,1),IF(n_FInicio="",TODAY(),n_FInicio)),IF(n_FInicio="",TODAY(),n_FInicio))))) | K24: =IF(C24="","",IF(M24<>"",M24,IF(D24="Hito",J24,J24+MAX(N(I24),1)-1))) | O24: =IF(C24="","",IF(N24<>"",N24,IF(M24<>"",1,IF(F24="",0,IF(D24="Instalación",MIN(1,IFERROR(SUMIFS('CORTES CLIENTE'!$O$20:$O$219,PRESUPUESTO!$V$7:$V$206,F24)/SUMIFS(PRESUPUESTO!$G$7:$G$206,PRESUPUESTO!$V$7:$V$206,F24),0)),IF(D24="Compra",MIN(1,IFERROR(SUMIFS('CONTROL DE MATERIALES'!$U$11:$U$210,PRESUPUESTO!$V$7:$V$206,F24)/SUMIFS('CONTROL DE MATERIALES'!$V$11:$V$210,PRESUPUESTO!$V$7:$V$206,F24),0)),0)))))) | P24: =IF(C24="","",IF(D24="Hito",IF(O24>=1,"Cumplido",IF(TODAY()>K24,"Vencido","Pendiente")),IF(O24>=1,"Terminada",IF(TODAY()>K24,"Atrasada",IF(OR(O24>0,L24<>""),"En curso",IF(TODAY()>=J24,"Debe iniciar","Por iniciar")))))) | Q24: =IF(OR(C24="",N(O24)>=1),"",IF(TODAY()>K24,TODAY()-K24,0)) | R24: =COUNTIF($D$8:D24,"Fase") -> 3 | S24: =IF(C24="","",J24) | T24: =IF(C24="","",K24) | U24: =IF(C24="","",MAX(N(I24),1)) | V24: =IF(C24="","",U24*N(O24)) | W24: =P24 | X24: =IF(Q24="","",N(Q24)) | Y24: =IF(AND($D24="Hito",ISNUMBER($K24)),IF(AND($K24>=Y$7,$K24<Y$7+7),"◆",""),"") | Z24: =IF(AND($D24="Hito",ISNUMBER($K24)),IF(AND($K24>=Z$7,$K24<Z$7+7),"◆",""),"") | AA24: =IF(AND($D24="Hito",ISNUMBER($K24)),IF(AND($K24>=AA$7,$K24<AA$7+7),"◆",""),"") | AB24: =IF(AND($D24="Hito",ISNUMBER($K24)),IF(AND($K24>=AB$7,$K24<AB$7+7),"◆",""),"") | AC24: =IF(AND($D24="Hito",ISNUMBER($K24)),IF(AND($K24>=AC$7,$K24<AC$7+7),"◆",""),"") | AD24: =IF(AND($D24="Hito",ISNUMBER($K24)),IF(AND($K24>=AD$7,$K24<AD$7+7),"◆",""),"") | AE24: =IF(AND($D24="Hito",ISNUMBER($K24)),IF(AND($K24>=AE$7,$K24<AE$7+7),"◆",""),"") | AF24: =IF(AND($D24="Hito",ISNUMBER($K24)),IF(AND($K24>=AF$7,$K24<AF$7+7),"◆",""),"") | ... BX24: =IF(AND($D24="Hito",ISNUMBER($K24)),IF(AND($K24>=BX$7,$K24<BX$7+7),"◆",""),"")
B25: ="F"&R25 -> F4 | C25: CORTES Y FACTURACIÓN | D25: Fase | I25: =IF(OR(J25="",K25=""),"",K25-J25+1) -> 1 | J25: =IFERROR(1/(1/_xlfn.MINIFS($S$8:$S$36,$R$8:$R$36,R25)),"") -> 46312 | K25: =IFERROR(1/(1/_xlfn.MAXIFS($T$8:$T$36,$R$8:$R$36,R25)),"") -> 46312 | O25: =IFERROR(SUMIFS($V$8:$V$36,$R$8:$R$36,R25)/SUMIFS($U$8:$U$36,$R$8:$R$36,R25),"") -> 0 | P25: =IF(COUNTIFS($R$8:$R$36,R25,$U$8:$U$36,">0")=0,"",IF(COUNTIFS($R$8:$R$36,R25,$W$8:$W$36,"Atrasada")+COUNTIFS($R$8:$R$36,R25,$W$8:$W$36,"Vencido")>0,"Con atraso",IF(N(O25)>=1,"Terminada",IF(N(O25)>0,"En curso","Por iniciar")))) -> Por iniciar | Q25: =IF(N(_xlfn.MAXIFS($X$8:$X$36,$R$8:$R$36,R25))>0,_xlfn.MAXIFS($X$8:$X$36,$R$8:$R$36,R25),"") | R25: =COUNTIF($D$8:D25,"Fase") -> 4
B26: 11 | C26: Acta de corte 1 al cliente | D26: Hito | E26: Dir. proyectos | I26: 0 | J26: =IF(C26="","",IF(L26<>"",L26,IF(H26<>"",H26,IF(G26<>"",IFERROR(INDEX($T$8:$T$36,MATCH(G26,$B$8:$B$36,0))+IF(D26="Hito",0,1),IF(n_FInicio="",TODAY(),n_FInicio)),IF(n_FInicio="",TODAY(),n_FInicio))))) -> 46312 | K26: =IF(C26="","",IF(M26<>"",M26,IF(D26="Hito",J26,J26+MAX(N(I26),1)-1))) -> 46312 | O26: =IF(C26="","",IF(N26<>"",N26,IF(M26<>"",1,IF(F26="",0,IF(D26="Instalación",MIN(1,IFERROR(SUMIFS('CORTES CLIENTE'!$O$20:$O$219,PRESUPUESTO!$V$7:$V$206,F26)/SUMIFS(PRESUPUESTO!$G$7:$G$206,PRESUPUESTO!$V$7:$V$206,F26),0)),IF(D26="Compra",MIN(1,IFERROR(SUMIFS('CONTROL DE MATERIALES'!$U$11:$U$210,PRESUPUESTO!$V$7:$V$206,F26)/SUMIFS('CONTROL DE MATERIALES'!$V$11:$V$210,PRESUPUESTO!$V$7:$V$206,F26),0)),0)))))) -> 0 | P26: =IF(C26="","",IF(D26="Hito",IF(O26>=1,"Cumplido",IF(TODAY()>K26,"Vencido","Pendiente")),IF(O26>=1,"Terminada",IF(TODAY()>K26,"Atrasada",IF(OR(O26>0,L26<>""),"En curso",IF(TODAY()>=J26,"Debe iniciar","Por iniciar")))))) -> Pendiente | Q26: =IF(OR(C26="",N(O26)>=1),"",IF(TODAY()>K26,TODAY()-K26,0)) -> 0 | R26: =COUNTIF($D$8:D26,"Fase") -> 4 | S26: =IF(C26="","",J26) -> 46312 | T26: =IF(C26="","",K26) -> 46312 | U26: =IF(C26="","",MAX(N(I26),1)) -> 1 | V26: =IF(C26="","",U26*N(O26)) -> 0 | W26: =P26 -> Pendiente | X26: =IF(Q26="","",N(Q26)) -> 0 | Y26: =IF(AND($D26="Hito",ISNUMBER($K26)),IF(AND($K26>=Y$7,$K26<Y$7+7),"◆",""),"") -> ◆ | Z26: =IF(AND($D26="Hito",ISNUMBER($K26)),IF(AND($K26>=Z$7,$K26<Z$7+7),"◆",""),"") | AA26: =IF(AND($D26="Hito",ISNUMBER($K26)),IF(AND($K26>=AA$7,$K26<AA$7+7),"◆",""),"") | AB26: =IF(AND($D26="Hito",ISNUMBER($K26)),IF(AND($K26>=AB$7,$K26<AB$7+7),"◆",""),"") | AC26: =IF(AND($D26="Hito",ISNUMBER($K26)),IF(AND($K26>=AC$7,$K26<AC$7+7),"◆",""),"") | AD26: =IF(AND($D26="Hito",ISNUMBER($K26)),IF(AND($K26>=AD$7,$K26<AD$7+7),"◆",""),"") | AE26: =IF(AND($D26="Hito",ISNUMBER($K26)),IF(AND($K26>=AE$7,$K26<AE$7+7),"◆",""),"") | AF26: =IF(AND($D26="Hito",ISNUMBER($K26)),IF(AND($K26>=AF$7,$K26<AF$7+7),"◆",""),"") | ... BX26: =IF(AND($D26="Hito",ISNUMBER($K26)),IF(AND($K26>=BX$7,$K26<BX$7+7),"◆",""),"")
J27: =IF(C27="","",IF(L27<>"",L27,IF(H27<>"",H27,IF(G27<>"",IFERROR(INDEX($T$8:$T$36,MATCH(G27,$B$8:$B$36,0))+IF(D27="Hito",0,1),IF(n_FInicio="",TODAY(),n_FInicio)),IF(n_FInicio="",TODAY(),n_FInicio))))) | K27: =IF(C27="","",IF(M27<>"",M27,IF(D27="Hito",J27,J27+MAX(N(I27),1)-1))) | O27: =IF(C27="","",IF(N27<>"",N27,IF(M27<>"",1,IF(F27="",0,IF(D27="Instalación",MIN(1,IFERROR(SUMIFS('CORTES CLIENTE'!$O$20:$O$219,PRESUPUESTO!$V$7:$V$206,F27)/SUMIFS(PRESUPUESTO!$G$7:$G$206,PRESUPUESTO!$V$7:$V$206,F27),0)),IF(D27="Compra",MIN(1,IFERROR(SUMIFS('CONTROL DE MATERIALES'!$U$11:$U$210,PRESUPUESTO!$V$7:$V$206,F27)/SUMIFS('CONTROL DE MATERIALES'!$V$11:$V$210,PRESUPUESTO!$V$7:$V$206,F27),0)),0)))))) | P27: =IF(C27="","",IF(D27="Hito",IF(O27>=1,"Cumplido",IF(TODAY()>K27,"Vencido","Pendiente")),IF(O27>=1,"Terminada",IF(TODAY()>K27,"Atrasada",IF(OR(O27>0,L27<>""),"En curso",IF(TODAY()>=J27,"Debe iniciar","Por iniciar")))))) | Q27: =IF(OR(C27="",N(O27)>=1),"",IF(TODAY()>K27,TODAY()-K27,0)) | R27: =COUNTIF($D$8:D27,"Fase") -> 4 | S27: =IF(C27="","",J27) | T27: =IF(C27="","",K27) | U27: =IF(C27="","",MAX(N(I27),1)) | V27: =IF(C27="","",U27*N(O27)) | W27: =P27 | X27: =IF(Q27="","",N(Q27)) | Y27: =IF(AND($D27="Hito",ISNUMBER($K27)),IF(AND($K27>=Y$7,$K27<Y$7+7),"◆",""),"") | Z27: =IF(AND($D27="Hito",ISNUMBER($K27)),IF(AND($K27>=Z$7,$K27<Z$7+7),"◆",""),"") | AA27: =IF(AND($D27="Hito",ISNUMBER($K27)),IF(AND($K27>=AA$7,$K27<AA$7+7),"◆",""),"") | AB27: =IF(AND($D27="Hito",ISNUMBER($K27)),IF(AND($K27>=AB$7,$K27<AB$7+7),"◆",""),"") | AC27: =IF(AND($D27="Hito",ISNUMBER($K27)),IF(AND($K27>=AC$7,$K27<AC$7+7),"◆",""),"") | AD27: =IF(AND($D27="Hito",ISNUMBER($K27)),IF(AND($K27>=AD$7,$K27<AD$7+7),"◆",""),"") | AE27: =IF(AND($D27="Hito",ISNUMBER($K27)),IF(AND($K27>=AE$7,$K27<AE$7+7),"◆",""),"") | AF27: =IF(AND($D27="Hito",ISNUMBER($K27)),IF(AND($K27>=AF$7,$K27<AF$7+7),"◆",""),"") | ... BX27: =IF(AND($D27="Hito",ISNUMBER($K27)),IF(AND($K27>=BX$7,$K27<BX$7+7),"◆",""),"")
B28: ="F"&R28 -> F5 | C28: CIERRE Y ENTREGA | D28: Fase | I28: =IF(OR(J28="",K28=""),"",K28-J28+1) -> 3 | J28: =IFERROR(1/(1/_xlfn.MINIFS($S$8:$S$36,$R$8:$R$36,R28)),"") -> 46346 | K28: =IFERROR(1/(1/_xlfn.MAXIFS($T$8:$T$36,$R$8:$R$36,R28)),"") -> 46348 | O28: =IFERROR(SUMIFS($V$8:$V$36,$R$8:$R$36,R28)/SUMIFS($U$8:$U$36,$R$8:$R$36,R28),"") -> 0 | P28: =IF(COUNTIFS($R$8:$R$36,R28,$U$8:$U$36,">0")=0,"",IF(COUNTIFS($R$8:$R$36,R28,$W$8:$W$36,"Atrasada")+COUNTIFS($R$8:$R$36,R28,$W$8:$W$36,"Vencido")>0,"Con atraso",IF(N(O28)>=1,"Terminada",IF(N(O28)>0,"En curso","Por iniciar")))) -> Por iniciar | Q28: =IF(N(_xlfn.MAXIFS($X$8:$X$36,$R$8:$R$36,R28))>0,_xlfn.MAXIFS($X$8:$X$36,$R$8:$R$36,R28),"") | R28: =COUNTIF($D$8:D28,"Fase") -> 5
B29: 12 | C29: Pruebas integrales y capacitación al cliente | D29: Pruebas | E29: Dir. proyectos | G29: 10 | I29: 3 | J29: =IF(C29="","",IF(L29<>"",L29,IF(H29<>"",H29,IF(G29<>"",IFERROR(INDEX($T$8:$T$36,MATCH(G29,$B$8:$B$36,0))+IF(D29="Hito",0,1),IF(n_FInicio="",TODAY(),n_FInicio)),IF(n_FInicio="",TODAY(),n_FInicio))))) -> 46346 | K29: =IF(C29="","",IF(M29<>"",M29,IF(D29="Hito",J29,J29+MAX(N(I29),1)-1))) -> 46348 | O29: =IF(C29="","",IF(N29<>"",N29,IF(M29<>"",1,IF(F29="",0,IF(D29="Instalación",MIN(1,IFERROR(SUMIFS('CORTES CLIENTE'!$O$20:$O$219,PRESUPUESTO!$V$7:$V$206,F29)/SUMIFS(PRESUPUESTO!$G$7:$G$206,PRESUPUESTO!$V$7:$V$206,F29),0)),IF(D29="Compra",MIN(1,IFERROR(SUMIFS('CONTROL DE MATERIALES'!$U$11:$U$210,PRESUPUESTO!$V$7:$V$206,F29)/SUMIFS('CONTROL DE MATERIALES'!$V$11:$V$210,PRESUPUESTO!$V$7:$V$206,F29),0)),0)))))) -> 0 | P29: =IF(C29="","",IF(D29="Hito",IF(O29>=1,"Cumplido",IF(TODAY()>K29,"Vencido","Pendiente")),IF(O29>=1,"Terminada",IF(TODAY()>K29,"Atrasada",IF(OR(O29>0,L29<>""),"En curso",IF(TODAY()>=J29,"Debe iniciar","Por iniciar")))))) -> Por iniciar | Q29: =IF(OR(C29="",N(O29)>=1),"",IF(TODAY()>K29,TODAY()-K29,0)) -> 0 | R29: =COUNTIF($D$8:D29,"Fase") -> 5 | S29: =IF(C29="","",J29) -> 46346 | T29: =IF(C29="","",K29) -> 46348 | U29: =IF(C29="","",MAX(N(I29),1)) -> 3 | V29: =IF(C29="","",U29*N(O29)) -> 0 | W29: =P29 -> Por iniciar | X29: =IF(Q29="","",N(Q29)) -> 0 | Y29: =IF(AND($D29="Hito",ISNUMBER($K29)),IF(AND($K29>=Y$7,$K29<Y$7+7),"◆",""),"") | Z29: =IF(AND($D29="Hito",ISNUMBER($K29)),IF(AND($K29>=Z$7,$K29<Z$7+7),"◆",""),"") | AA29: =IF(AND($D29="Hito",ISNUMBER($K29)),IF(AND($K29>=AA$7,$K29<AA$7+7),"◆",""),"") | AB29: =IF(AND($D29="Hito",ISNUMBER($K29)),IF(AND($K29>=AB$7,$K29<AB$7+7),"◆",""),"") | AC29: =IF(AND($D29="Hito",ISNUMBER($K29)),IF(AND($K29>=AC$7,$K29<AC$7+7),"◆",""),"") | AD29: =IF(AND($D29="Hito",ISNUMBER($K29)),IF(AND($K29>=AD$7,$K29<AD$7+7),"◆",""),"") | AE29: =IF(AND($D29="Hito",ISNUMBER($K29)),IF(AND($K29>=AE$7,$K29<AE$7+7),"◆",""),"") | AF29: =IF(AND($D29="Hito",ISNUMBER($K29)),IF(AND($K29>=AF$7,$K29<AF$7+7),"◆",""),"") | ... BX29: =IF(AND($D29="Hito",ISNUMBER($K29)),IF(AND($K29>=BX$7,$K29<BX$7+7),"◆",""),"")
B30: 13 | C30: Entrega y acta de recibo final | D30: Hito | E30: Dir. proyectos | G30: 12 | I30: 0 | J30: =IF(C30="","",IF(L30<>"",L30,IF(H30<>"",H30,IF(G30<>"",IFERROR(INDEX($T$8:$T$36,MATCH(G30,$B$8:$B$36,0))+IF(D30="Hito",0,1),IF(n_FInicio="",TODAY(),n_FInicio)),IF(n_FInicio="",TODAY(),n_FInicio))))) -> 46348 | K30: =IF(C30="","",IF(M30<>"",M30,IF(D30="Hito",J30,J30+MAX(N(I30),1)-1))) -> 46348 | O30: =IF(C30="","",IF(N30<>"",N30,IF(M30<>"",1,IF(F30="",0,IF(D30="Instalación",MIN(1,IFERROR(SUMIFS('CORTES CLIENTE'!$O$20:$O$219,PRESUPUESTO!$V$7:$V$206,F30)/SUMIFS(PRESUPUESTO!$G$7:$G$206,PRESUPUESTO!$V$7:$V$206,F30),0)),IF(D30="Compra",MIN(1,IFERROR(SUMIFS('CONTROL DE MATERIALES'!$U$11:$U$210,PRESUPUESTO!$V$7:$V$206,F30)/SUMIFS('CONTROL DE MATERIALES'!$V$11:$V$210,PRESUPUESTO!$V$7:$V$206,F30),0)),0)))))) -> 0 | P30: =IF(C30="","",IF(D30="Hito",IF(O30>=1,"Cumplido",IF(TODAY()>K30,"Vencido","Pendiente")),IF(O30>=1,"Terminada",IF(TODAY()>K30,"Atrasada",IF(OR(O30>0,L30<>""),"En curso",IF(TODAY()>=J30,"Debe iniciar","Por iniciar")))))) -> Pendiente | Q30: =IF(OR(C30="",N(O30)>=1),"",IF(TODAY()>K30,TODAY()-K30,0)) -> 0 | R30: =COUNTIF($D$8:D30,"Fase") -> 5 | S30: =IF(C30="","",J30) -> 46348 | T30: =IF(C30="","",K30) -> 46348 | U30: =IF(C30="","",MAX(N(I30),1)) -> 1 | V30: =IF(C30="","",U30*N(O30)) -> 0 | W30: =P30 -> Pendiente | X30: =IF(Q30="","",N(Q30)) -> 0 | Y30: =IF(AND($D30="Hito",ISNUMBER($K30)),IF(AND($K30>=Y$7,$K30<Y$7+7),"◆",""),"") | Z30: =IF(AND($D30="Hito",ISNUMBER($K30)),IF(AND($K30>=Z$7,$K30<Z$7+7),"◆",""),"") | AA30: =IF(AND($D30="Hito",ISNUMBER($K30)),IF(AND($K30>=AA$7,$K30<AA$7+7),"◆",""),"") | AB30: =IF(AND($D30="Hito",ISNUMBER($K30)),IF(AND($K30>=AB$7,$K30<AB$7+7),"◆",""),"") | AC30: =IF(AND($D30="Hito",ISNUMBER($K30)),IF(AND($K30>=AC$7,$K30<AC$7+7),"◆",""),"") | AD30: =IF(AND($D30="Hito",ISNUMBER($K30)),IF(AND($K30>=AD$7,$K30<AD$7+7),"◆",""),"") -> ◆ | AE30: =IF(AND($D30="Hito",ISNUMBER($K30)),IF(AND($K30>=AE$7,$K30<AE$7+7),"◆",""),"") | AF30: =IF(AND($D30="Hito",ISNUMBER($K30)),IF(AND($K30>=AF$7,$K30<AF$7+7),"◆",""),"") | ... BX30: =IF(AND($D30="Hito",ISNUMBER($K30)),IF(AND($K30>=BX$7,$K30<BX$7+7),"◆",""),"")
B31: 14 | C31: Liquidación del contrato | D31: Hito | E31: Gerencia | G31: 13 | I31: 0 | J31: =IF(C31="","",IF(L31<>"",L31,IF(H31<>"",H31,IF(G31<>"",IFERROR(INDEX($T$8:$T$36,MATCH(G31,$B$8:$B$36,0))+IF(D31="Hito",0,1),IF(n_FInicio="",TODAY(),n_FInicio)),IF(n_FInicio="",TODAY(),n_FInicio))))) -> 46348 | K31: =IF(C31="","",IF(M31<>"",M31,IF(D31="Hito",J31,J31+MAX(N(I31),1)-1))) -> 46348 | O31: =IF(C31="","",IF(N31<>"",N31,IF(M31<>"",1,IF(F31="",0,IF(D31="Instalación",MIN(1,IFERROR(SUMIFS('CORTES CLIENTE'!$O$20:$O$219,PRESUPUESTO!$V$7:$V$206,F31)/SUMIFS(PRESUPUESTO!$G$7:$G$206,PRESUPUESTO!$V$7:$V$206,F31),0)),IF(D31="Compra",MIN(1,IFERROR(SUMIFS('CONTROL DE MATERIALES'!$U$11:$U$210,PRESUPUESTO!$V$7:$V$206,F31)/SUMIFS('CONTROL DE MATERIALES'!$V$11:$V$210,PRESUPUESTO!$V$7:$V$206,F31),0)),0)))))) -> 0 | P31: =IF(C31="","",IF(D31="Hito",IF(O31>=1,"Cumplido",IF(TODAY()>K31,"Vencido","Pendiente")),IF(O31>=1,"Terminada",IF(TODAY()>K31,"Atrasada",IF(OR(O31>0,L31<>""),"En curso",IF(TODAY()>=J31,"Debe iniciar","Por iniciar")))))) -> Pendiente | Q31: =IF(OR(C31="",N(O31)>=1),"",IF(TODAY()>K31,TODAY()-K31,0)) -> 0 | R31: =COUNTIF($D$8:D31,"Fase") -> 5 | S31: =IF(C31="","",J31) -> 46348 | T31: =IF(C31="","",K31) -> 46348 | U31: =IF(C31="","",MAX(N(I31),1)) -> 1 | V31: =IF(C31="","",U31*N(O31)) -> 0 | W31: =P31 -> Pendiente | X31: =IF(Q31="","",N(Q31)) -> 0 | Y31: =IF(AND($D31="Hito",ISNUMBER($K31)),IF(AND($K31>=Y$7,$K31<Y$7+7),"◆",""),"") | Z31: =IF(AND($D31="Hito",ISNUMBER($K31)),IF(AND($K31>=Z$7,$K31<Z$7+7),"◆",""),"") | AA31: =IF(AND($D31="Hito",ISNUMBER($K31)),IF(AND($K31>=AA$7,$K31<AA$7+7),"◆",""),"") | AB31: =IF(AND($D31="Hito",ISNUMBER($K31)),IF(AND($K31>=AB$7,$K31<AB$7+7),"◆",""),"") | AC31: =IF(AND($D31="Hito",ISNUMBER($K31)),IF(AND($K31>=AC$7,$K31<AC$7+7),"◆",""),"") | AD31: =IF(AND($D31="Hito",ISNUMBER($K31)),IF(AND($K31>=AD$7,$K31<AD$7+7),"◆",""),"") -> ◆ | AE31: =IF(AND($D31="Hito",ISNUMBER($K31)),IF(AND($K31>=AE$7,$K31<AE$7+7),"◆",""),"") | AF31: =IF(AND($D31="Hito",ISNUMBER($K31)),IF(AND($K31>=AF$7,$K31<AF$7+7),"◆",""),"") | ... BX31: =IF(AND($D31="Hito",ISNUMBER($K31)),IF(AND($K31>=BX$7,$K31<BX$7+7),"◆",""),"")
